//Schematic to java Structure by jajo_11 | inspired by "MITHION'S .SCHEMATIC TO JAVA CONVERTINGTOOL
package com.github.alexthe666.iat.world.gen.timedungeon;

import java.util.Random;

import net.minecraft.block.Block;
import net.minecraft.block.material.Material;
import net.minecraft.init.Blocks;
import net.minecraft.util.BlockPos;
import net.minecraft.world.World;
import net.minecraft.world.gen.feature.WorldGenerator;

import com.github.alexthe666.iat.core.ModBlocks;
import com.github.alexthe666.iat.world.WorldUtils;

public class WorldGenTimeDungeon extends WorldGenerator
{

	public boolean generate(World world, Random rand, BlockPos pos)
	{
		generate_r0(world, rand, pos.getX(), pos.getY(), pos.getZ());
		return true;

	}

	public boolean generate_r0(World world, Random rand, int x, int y, int z)
	{
		WorldUtils.setBlock(world, x + 8, y + 0, z + 0, Blocks.stonebrick, rand.nextInt(3), 3);
		WorldUtils.setBlock(world, x + 7, y + 0, z + 1, Blocks.stonebrick, rand.nextInt(3), 3);
		WorldUtils.setBlock(world, x + 8, y + 0, z + 1, Blocks.stone, 6, 3);
		WorldUtils.setBlock(world, x + 9, y + 0, z + 1, Blocks.stonebrick, rand.nextInt(3), 3);
		WorldUtils.setBlock(world, x + 7, y + 0, z + 2, Blocks.stonebrick, rand.nextInt(3), 3);
		WorldUtils.setBlock(world, x + 8, y + 0, z + 2, Blocks.stone, 6, 3);
		WorldUtils.setBlock(world, x + 9, y + 0, z + 2, Blocks.stonebrick, rand.nextInt(3), 3);
		WorldUtils.setBlock(world, x + 1, y + 0, z + 3, Blocks.stonebrick, rand.nextInt(3), 3);
		WorldUtils.setBlock(world, x + 2, y + 0, z + 3, Blocks.stonebrick, rand.nextInt(3), 3);
		WorldUtils.setBlock(world, x + 3, y + 0, z + 3, Blocks.stonebrick, rand.nextInt(3), 3);
		WorldUtils.setBlock(world, x + 4, y + 0, z + 3, Blocks.stonebrick, rand.nextInt(3), 3);
		WorldUtils.setBlock(world, x + 5, y + 0, z + 3, Blocks.stonebrick, rand.nextInt(3), 3);
		WorldUtils.setBlock(world, x + 6, y + 0, z + 3, Blocks.stonebrick, rand.nextInt(3), 3);
		WorldUtils.setBlock(world, x + 7, y + 0, z + 3, Blocks.stonebrick, rand.nextInt(3), 3);
		WorldUtils.setBlock(world, x + 8, y + 0, z + 3, Blocks.stone, 6, 3);
		WorldUtils.setBlock(world, x + 9, y + 0, z + 3, Blocks.stonebrick, rand.nextInt(3), 3);
		WorldUtils.setBlock(world, x + 10, y + 0, z + 3, Blocks.stonebrick, rand.nextInt(3), 3);
		WorldUtils.setBlock(world, x + 11, y + 0, z + 3, Blocks.stonebrick, rand.nextInt(3), 3);
		WorldUtils.setBlock(world, x + 12, y + 0, z + 3, Blocks.stonebrick, rand.nextInt(3), 3);
		WorldUtils.setBlock(world, x + 13, y + 0, z + 3, Blocks.stonebrick, rand.nextInt(3), 3);
		WorldUtils.setBlock(world, x + 14, y + 0, z + 3, Blocks.stonebrick, rand.nextInt(3), 3);
		WorldUtils.setBlock(world, x + 15, y + 0, z + 3, Blocks.stonebrick, rand.nextInt(3), 3);
		WorldUtils.setBlock(world, x + 1, y + 0, z + 4, Blocks.stonebrick, rand.nextInt(3), 3);
		WorldUtils.setBlock(world, x + 2, y + 0, z + 4, Blocks.stonebrick, rand.nextInt(3), 3);
		WorldUtils.setBlock(world, x + 3, y + 0, z + 4, Blocks.stonebrick, rand.nextInt(3), 3);
		WorldUtils.setBlock(world, x + 4, y + 0, z + 4, Blocks.stonebrick, rand.nextInt(3), 3);
		WorldUtils.setBlock(world, x + 5, y + 0, z + 4, Blocks.stonebrick, rand.nextInt(3), 3);
		WorldUtils.setBlock(world, x + 6, y + 0, z + 4, Blocks.stonebrick, rand.nextInt(3), 3);
		WorldUtils.setBlock(world, x + 7, y + 0, z + 4, Blocks.stonebrick, rand.nextInt(3), 3);
		WorldUtils.setBlock(world, x + 8, y + 0, z + 4, Blocks.stone, 6, 3);
		WorldUtils.setBlock(world, x + 9, y + 0, z + 4, Blocks.stonebrick, rand.nextInt(3), 3);
		WorldUtils.setBlock(world, x + 10, y + 0, z + 4, Blocks.stonebrick, rand.nextInt(3), 3);
		WorldUtils.setBlock(world, x + 11, y + 0, z + 4, Blocks.stonebrick, rand.nextInt(3), 3);
		WorldUtils.setBlock(world, x + 12, y + 0, z + 4, Blocks.stonebrick, rand.nextInt(3), 3);
		WorldUtils.setBlock(world, x + 13, y + 0, z + 4, Blocks.stonebrick, rand.nextInt(3), 3);
		WorldUtils.setBlock(world, x + 14, y + 0, z + 4, Blocks.stonebrick, rand.nextInt(3), 3);
		WorldUtils.setBlock(world, x + 15, y + 0, z + 4, Blocks.stonebrick, rand.nextInt(3), 3);
		WorldUtils.setBlock(world, x + 1, y + 0, z + 5, Blocks.stonebrick, rand.nextInt(3), 3);
		WorldUtils.setBlock(world, x + 2, y + 0, z + 5, Blocks.stonebrick, rand.nextInt(3), 3);
		WorldUtils.setBlock(world, x + 3, y + 0, z + 5, Blocks.stone, 6, 3);
		WorldUtils.setBlock(world, x + 4, y + 0, z + 5, Blocks.stone, 6, 3);
		WorldUtils.setBlock(world, x + 5, y + 0, z + 5, Blocks.stone, 6, 3);
		WorldUtils.setBlock(world, x + 6, y + 0, z + 5, Blocks.stone, 6, 3);
		WorldUtils.setBlock(world, x + 7, y + 0, z + 5, Blocks.stone, 6, 3);
		WorldUtils.setBlock(world, x + 8, y + 0, z + 5, Blocks.stone, 6, 3);
		WorldUtils.setBlock(world, x + 9, y + 0, z + 5, Blocks.stone, 6, 3);
		WorldUtils.setBlock(world, x + 10, y + 0, z + 5, Blocks.stone, 6, 3);
		WorldUtils.setBlock(world, x + 11, y + 0, z + 5, Blocks.stone, 6, 3);
		WorldUtils.setBlock(world, x + 12, y + 0, z + 5, Blocks.stone, 6, 3);
		WorldUtils.setBlock(world, x + 13, y + 0, z + 5, Blocks.stone, 6, 3);
		WorldUtils.setBlock(world, x + 14, y + 0, z + 5, Blocks.stonebrick, rand.nextInt(3), 3);
		WorldUtils.setBlock(world, x + 15, y + 0, z + 5, Blocks.stonebrick, rand.nextInt(3), 3);
		WorldUtils.setBlock(world, x + 1, y + 0, z + 6, Blocks.stonebrick, rand.nextInt(3), 3);
		WorldUtils.setBlock(world, x + 2, y + 0, z + 6, Blocks.stonebrick, rand.nextInt(3), 3);
		WorldUtils.setBlock(world, x + 3, y + 0, z + 6, Blocks.stone, 6, 3);
		WorldUtils.setBlock(world, x + 4, y + 0, z + 6, Blocks.stone, 6, 3);
		WorldUtils.setBlock(world, x + 5, y + 0, z + 6, Blocks.stone, 6, 3);
		WorldUtils.setBlock(world, x + 6, y + 0, z + 6, Blocks.stone, 6, 3);
		WorldUtils.setBlock(world, x + 7, y + 0, z + 6, Blocks.stone, 6, 3);
		WorldUtils.setBlock(world, x + 8, y + 0, z + 6, Blocks.stone, 6, 3);
		WorldUtils.setBlock(world, x + 9, y + 0, z + 6, Blocks.stone, 6, 3);
		WorldUtils.setBlock(world, x + 10, y + 0, z + 6, Blocks.stone, 6, 3);
		WorldUtils.setBlock(world, x + 11, y + 0, z + 6, Blocks.stone, 6, 3);
		WorldUtils.setBlock(world, x + 12, y + 0, z + 6, Blocks.stone, 6, 3);
		WorldUtils.setBlock(world, x + 13, y + 0, z + 6, Blocks.stone, 6, 3);
		WorldUtils.setBlock(world, x + 14, y + 0, z + 6, Blocks.stonebrick, rand.nextInt(3), 3);
		WorldUtils.setBlock(world, x + 15, y + 0, z + 6, Blocks.stonebrick, rand.nextInt(3), 3);
		WorldUtils.setBlock(world, x + 1, y + 0, z + 7, Blocks.stonebrick, rand.nextInt(3), 3);
		WorldUtils.setBlock(world, x + 2, y + 0, z + 7, Blocks.stonebrick, rand.nextInt(3), 3);
		WorldUtils.setBlock(world, x + 3, y + 0, z + 7, Blocks.stone, 6, 3);
		WorldUtils.setBlock(world, x + 4, y + 0, z + 7, Blocks.stone, 6, 3);
		WorldUtils.setBlock(world, x + 5, y + 0, z + 7, Blocks.stone, 6, 3);
		WorldUtils.setBlock(world, x + 6, y + 0, z + 7, Blocks.stone, 6, 3);
		WorldUtils.setBlock(world, x + 7, y + 0, z + 7, Blocks.stone, 6, 3);
		WorldUtils.setBlock(world, x + 8, y + 0, z + 7, Blocks.stone, 6, 3);
		WorldUtils.setBlock(world, x + 9, y + 0, z + 7, Blocks.stone, 6, 3);
		WorldUtils.setBlock(world, x + 10, y + 0, z + 7, Blocks.stone, 6, 3);
		WorldUtils.setBlock(world, x + 11, y + 0, z + 7, Blocks.stone, 6, 3);
		WorldUtils.setBlock(world, x + 12, y + 0, z + 7, Blocks.stone, 6, 3);
		WorldUtils.setBlock(world, x + 13, y + 0, z + 7, Blocks.stone, 6, 3);
		WorldUtils.setBlock(world, x + 14, y + 0, z + 7, Blocks.stonebrick, rand.nextInt(3), 3);
		WorldUtils.setBlock(world, x + 15, y + 0, z + 7, Blocks.stonebrick, rand.nextInt(3), 3);
		WorldUtils.setBlock(world, x + 1, y + 0, z + 8, Blocks.stonebrick, rand.nextInt(3), 3);
		WorldUtils.setBlock(world, x + 2, y + 0, z + 8, Blocks.stonebrick, rand.nextInt(3), 3);
		WorldUtils.setBlock(world, x + 3, y + 0, z + 8, Blocks.stone, 6, 3);
		WorldUtils.setBlock(world, x + 4, y + 0, z + 8, Blocks.stone, 6, 3);
		WorldUtils.setBlock(world, x + 5, y + 0, z + 8, Blocks.stone, 6, 3);
		WorldUtils.setBlock(world, x + 6, y + 0, z + 8, Blocks.stone, 6, 3);
		WorldUtils.setBlock(world, x + 7, y + 0, z + 8, Blocks.stone, 6, 3);
		WorldUtils.setBlock(world, x + 8, y + 0, z + 8, Blocks.stone, 6, 3);
		WorldUtils.setBlock(world, x + 9, y + 0, z + 8, Blocks.stone, 6, 3);
		WorldUtils.setBlock(world, x + 10, y + 0, z + 8, Blocks.stone, 6, 3);
		WorldUtils.setBlock(world, x + 11, y + 0, z + 8, Blocks.stone, 6, 3);
		WorldUtils.setBlock(world, x + 12, y + 0, z + 8, Blocks.stone, 6, 3);
		WorldUtils.setBlock(world, x + 13, y + 0, z + 8, Blocks.stone, 6, 3);
		WorldUtils.setBlock(world, x + 14, y + 0, z + 8, Blocks.stonebrick, rand.nextInt(3), 3);
		WorldUtils.setBlock(world, x + 15, y + 0, z + 8, Blocks.stonebrick, rand.nextInt(3), 3);
		WorldUtils.setBlock(world, x + 1, y + 0, z + 9, Blocks.stonebrick, rand.nextInt(3), 3);
		WorldUtils.setBlock(world, x + 2, y + 0, z + 9, Blocks.stonebrick, rand.nextInt(3), 3);
		WorldUtils.setBlock(world, x + 3, y + 0, z + 9, Blocks.stone, 6, 3);
		WorldUtils.setBlock(world, x + 4, y + 0, z + 9, Blocks.stone, 6, 3);
		WorldUtils.setBlock(world, x + 5, y + 0, z + 9, Blocks.stone, 6, 3);
		WorldUtils.setBlock(world, x + 6, y + 0, z + 9, Blocks.stone, 6, 3);
		WorldUtils.setBlock(world, x + 7, y + 0, z + 9, Blocks.stone, 6, 3);
		WorldUtils.setBlock(world, x + 8, y + 0, z + 9, Blocks.stone, 6, 3);
		WorldUtils.setBlock(world, x + 9, y + 0, z + 9, Blocks.stone, 6, 3);
		WorldUtils.setBlock(world, x + 10, y + 0, z + 9, Blocks.stone, 6, 3);
		WorldUtils.setBlock(world, x + 11, y + 0, z + 9, Blocks.stone, 6, 3);
		WorldUtils.setBlock(world, x + 12, y + 0, z + 9, Blocks.stone, 6, 3);
		WorldUtils.setBlock(world, x + 13, y + 0, z + 9, Blocks.stone, 6, 3);
		WorldUtils.setBlock(world, x + 14, y + 0, z + 9, Blocks.stonebrick, rand.nextInt(3), 3);
		WorldUtils.setBlock(world, x + 15, y + 0, z + 9, Blocks.stonebrick, rand.nextInt(3), 3);
		WorldUtils.setBlock(world, x + 1, y + 0, z + 10, Blocks.stonebrick, rand.nextInt(3), 3);
		WorldUtils.setBlock(world, x + 2, y + 0, z + 10, Blocks.stonebrick, rand.nextInt(3), 3);
		WorldUtils.setBlock(world, x + 3, y + 0, z + 10, Blocks.stone, 6, 3);
		WorldUtils.setBlock(world, x + 4, y + 0, z + 10, Blocks.stone, 6, 3);
		WorldUtils.setBlock(world, x + 5, y + 0, z + 10, Blocks.stone, 6, 3);
		WorldUtils.setBlock(world, x + 6, y + 0, z + 10, Blocks.stone, 6, 3);
		WorldUtils.setBlock(world, x + 7, y + 0, z + 10, Blocks.stone, 6, 3);
		WorldUtils.setBlock(world, x + 8, y + 0, z + 10, Blocks.stone, 6, 3);
		WorldUtils.setBlock(world, x + 9, y + 0, z + 10, Blocks.stone, 6, 3);
		WorldUtils.setBlock(world, x + 10, y + 0, z + 10, Blocks.stone, 6, 3);
		WorldUtils.setBlock(world, x + 11, y + 0, z + 10, Blocks.stone, 6, 3);
		WorldUtils.setBlock(world, x + 12, y + 0, z + 10, Blocks.stone, 6, 3);
		WorldUtils.setBlock(world, x + 13, y + 0, z + 10, Blocks.stone, 6, 3);
		WorldUtils.setBlock(world, x + 14, y + 0, z + 10, Blocks.stonebrick, rand.nextInt(3), 3);
		WorldUtils.setBlock(world, x + 15, y + 0, z + 10, Blocks.stonebrick, rand.nextInt(3), 3);
		WorldUtils.setBlock(world, x + 1, y + 0, z + 11, Blocks.stonebrick, rand.nextInt(3), 3);
		WorldUtils.setBlock(world, x + 2, y + 0, z + 11, Blocks.stonebrick, rand.nextInt(3), 3);
		WorldUtils.setBlock(world, x + 3, y + 0, z + 11, Blocks.stone, 6, 3);
		WorldUtils.setBlock(world, x + 4, y + 0, z + 11, Blocks.stone, 6, 3);
		WorldUtils.setBlock(world, x + 5, y + 0, z + 11, Blocks.stone, 6, 3);
		WorldUtils.setBlock(world, x + 6, y + 0, z + 11, Blocks.stone, 6, 3);
		WorldUtils.setBlock(world, x + 7, y + 0, z + 11, Blocks.stone, 6, 3);
		WorldUtils.setBlock(world, x + 8, y + 0, z + 11, Blocks.stone, 6, 3);
		WorldUtils.setBlock(world, x + 9, y + 0, z + 11, Blocks.stone, 6, 3);
		WorldUtils.setBlock(world, x + 10, y + 0, z + 11, Blocks.stone, 6, 3);
		WorldUtils.setBlock(world, x + 11, y + 0, z + 11, Blocks.stone, 6, 3);
		WorldUtils.setBlock(world, x + 12, y + 0, z + 11, Blocks.stone, 6, 3);
		WorldUtils.setBlock(world, x + 13, y + 0, z + 11, Blocks.stone, 6, 3);
		WorldUtils.setBlock(world, x + 14, y + 0, z + 11, Blocks.stonebrick, rand.nextInt(3), 3);
		WorldUtils.setBlock(world, x + 15, y + 0, z + 11, Blocks.stonebrick, rand.nextInt(3), 3);
		WorldUtils.setBlock(world, x + 1, y + 0, z + 12, Blocks.stonebrick, rand.nextInt(3), 3);
		WorldUtils.setBlock(world, x + 2, y + 0, z + 12, Blocks.stonebrick, rand.nextInt(3), 3);
		WorldUtils.setBlock(world, x + 3, y + 0, z + 12, Blocks.stone, 6, 3);
		WorldUtils.setBlock(world, x + 4, y + 0, z + 12, Blocks.stone, 6, 3);
		WorldUtils.setBlock(world, x + 5, y + 0, z + 12, Blocks.stone, 6, 3);
		WorldUtils.setBlock(world, x + 6, y + 0, z + 12, Blocks.stone, 6, 3);
		WorldUtils.setBlock(world, x + 7, y + 0, z + 12, Blocks.stone, 6, 3);
		WorldUtils.setBlock(world, x + 8, y + 0, z + 12, Blocks.stone, 6, 3);
		WorldUtils.setBlock(world, x + 9, y + 0, z + 12, Blocks.stone, 6, 3);
		WorldUtils.setBlock(world, x + 10, y + 0, z + 12, Blocks.stone, 6, 3);
		WorldUtils.setBlock(world, x + 11, y + 0, z + 12, Blocks.stone, 6, 3);
		WorldUtils.setBlock(world, x + 12, y + 0, z + 12, Blocks.stone, 6, 3);
		WorldUtils.setBlock(world, x + 13, y + 0, z + 12, Blocks.stone, 6, 3);
		WorldUtils.setBlock(world, x + 14, y + 0, z + 12, Blocks.stonebrick, rand.nextInt(3), 3);
		WorldUtils.setBlock(world, x + 15, y + 0, z + 12, Blocks.stonebrick, rand.nextInt(3), 3);
		WorldUtils.setBlock(world, x + 1, y + 0, z + 13, Blocks.stonebrick, rand.nextInt(3), 3);
		WorldUtils.setBlock(world, x + 2, y + 0, z + 13, Blocks.stonebrick, rand.nextInt(3), 3);
		WorldUtils.setBlock(world, x + 3, y + 0, z + 13, Blocks.stone, 6, 3);
		WorldUtils.setBlock(world, x + 4, y + 0, z + 13, Blocks.stone, 6, 3);
		WorldUtils.setBlock(world, x + 5, y + 0, z + 13, Blocks.stone, 6, 3);
		WorldUtils.setBlock(world, x + 6, y + 0, z + 13, Blocks.stone, 6, 3);
		WorldUtils.setBlock(world, x + 7, y + 0, z + 13, Blocks.stone, 6, 3);
		WorldUtils.setBlock(world, x + 8, y + 0, z + 13, Blocks.stone, 6, 3);
		WorldUtils.setBlock(world, x + 9, y + 0, z + 13, Blocks.stone, 6, 3);
		WorldUtils.setBlock(world, x + 10, y + 0, z + 13, Blocks.stone, 6, 3);
		WorldUtils.setBlock(world, x + 11, y + 0, z + 13, Blocks.stone, 6, 3);
		WorldUtils.setBlock(world, x + 12, y + 0, z + 13, Blocks.stone, 6, 3);
		WorldUtils.setBlock(world, x + 13, y + 0, z + 13, Blocks.stone, 6, 3);
		WorldUtils.setBlock(world, x + 14, y + 0, z + 13, Blocks.stonebrick, rand.nextInt(3), 3);
		WorldUtils.setBlock(world, x + 15, y + 0, z + 13, Blocks.stonebrick, rand.nextInt(3), 3);
		WorldUtils.setBlock(world, x + 1, y + 0, z + 14, Blocks.stonebrick, rand.nextInt(3), 3);
		WorldUtils.setBlock(world, x + 2, y + 0, z + 14, Blocks.stonebrick, rand.nextInt(3), 3);
		WorldUtils.setBlock(world, x + 3, y + 0, z + 14, Blocks.stone, 6, 3);
		WorldUtils.setBlock(world, x + 4, y + 0, z + 14, Blocks.stone, 6, 3);
		WorldUtils.setBlock(world, x + 5, y + 0, z + 14, Blocks.stone, 6, 3);
		WorldUtils.setBlock(world, x + 6, y + 0, z + 14, Blocks.stone, 6, 3);
		WorldUtils.setBlock(world, x + 7, y + 0, z + 14, Blocks.stone, 6, 3);
		WorldUtils.setBlock(world, x + 8, y + 0, z + 14, Blocks.stone, 6, 3);
		WorldUtils.setBlock(world, x + 9, y + 0, z + 14, Blocks.stone, 6, 3);
		WorldUtils.setBlock(world, x + 10, y + 0, z + 14, Blocks.stone, 6, 3);
		WorldUtils.setBlock(world, x + 11, y + 0, z + 14, Blocks.stone, 6, 3);
		WorldUtils.setBlock(world, x + 12, y + 0, z + 14, Blocks.stone, 6, 3);
		WorldUtils.setBlock(world, x + 13, y + 0, z + 14, Blocks.stone, 6, 3);
		WorldUtils.setBlock(world, x + 14, y + 0, z + 14, Blocks.stonebrick, rand.nextInt(3), 3);
		WorldUtils.setBlock(world, x + 15, y + 0, z + 14, Blocks.stonebrick, rand.nextInt(3), 3);
		WorldUtils.setBlock(world, x + 1, y + 0, z + 15, Blocks.stonebrick, rand.nextInt(3), 3);
		WorldUtils.setBlock(world, x + 2, y + 0, z + 15, Blocks.stonebrick, rand.nextInt(3), 3);
		WorldUtils.setBlock(world, x + 3, y + 0, z + 15, Blocks.stonebrick, rand.nextInt(3), 3);
		WorldUtils.setBlock(world, x + 4, y + 0, z + 15, Blocks.stonebrick, rand.nextInt(3), 3);
		WorldUtils.setBlock(world, x + 5, y + 0, z + 15, Blocks.stonebrick, rand.nextInt(3), 3);
		WorldUtils.setBlock(world, x + 6, y + 0, z + 15, Blocks.stonebrick, rand.nextInt(3), 3);
		WorldUtils.setBlock(world, x + 7, y + 0, z + 15, Blocks.stonebrick, rand.nextInt(3), 3);
		WorldUtils.setBlock(world, x + 8, y + 0, z + 15, Blocks.stonebrick, rand.nextInt(3), 3);
		WorldUtils.setBlock(world, x + 9, y + 0, z + 15, Blocks.stonebrick, rand.nextInt(3), 3);
		WorldUtils.setBlock(world, x + 10, y + 0, z + 15, Blocks.stonebrick, rand.nextInt(3), 3);
		WorldUtils.setBlock(world, x + 11, y + 0, z + 15, Blocks.stonebrick, rand.nextInt(3), 3);
		WorldUtils.setBlock(world, x + 12, y + 0, z + 15, Blocks.stonebrick, rand.nextInt(3), 3);
		WorldUtils.setBlock(world, x + 13, y + 0, z + 15, Blocks.stonebrick, rand.nextInt(3), 3);
		WorldUtils.setBlock(world, x + 14, y + 0, z + 15, Blocks.stonebrick, rand.nextInt(3), 3);
		WorldUtils.setBlock(world, x + 15, y + 0, z + 15, Blocks.stonebrick, rand.nextInt(3), 3);
		WorldUtils.setBlock(world, x + 1, y + 0, z + 16, Blocks.stonebrick, rand.nextInt(3), 3);
		WorldUtils.setBlock(world, x + 2, y + 0, z + 16, Blocks.stonebrick, rand.nextInt(3), 3);
		WorldUtils.setBlock(world, x + 3, y + 0, z + 16, Blocks.stonebrick, rand.nextInt(3), 3);
		WorldUtils.setBlock(world, x + 4, y + 0, z + 16, Blocks.stonebrick, rand.nextInt(3), 3);
		WorldUtils.setBlock(world, x + 5, y + 0, z + 16, Blocks.stonebrick, rand.nextInt(3), 3);
		WorldUtils.setBlock(world, x + 6, y + 0, z + 16, Blocks.stonebrick, rand.nextInt(3), 3);
		WorldUtils.setBlock(world, x + 7, y + 0, z + 16, Blocks.stonebrick, rand.nextInt(3), 3);
		WorldUtils.setBlock(world, x + 8, y + 0, z + 16, Blocks.stonebrick, rand.nextInt(3), 3);
		WorldUtils.setBlock(world, x + 9, y + 0, z + 16, Blocks.stonebrick, rand.nextInt(3), 3);
		WorldUtils.setBlock(world, x + 10, y + 0, z + 16, Blocks.stonebrick, rand.nextInt(3), 3);
		WorldUtils.setBlock(world, x + 11, y + 0, z + 16, Blocks.stonebrick, rand.nextInt(3), 3);
		WorldUtils.setBlock(world, x + 12, y + 0, z + 16, Blocks.stonebrick, rand.nextInt(3), 3);
		WorldUtils.setBlock(world, x + 13, y + 0, z + 16, Blocks.stonebrick, rand.nextInt(3), 3);
		WorldUtils.setBlock(world, x + 14, y + 0, z + 16, Blocks.stonebrick, rand.nextInt(3), 3);
		WorldUtils.setBlock(world, x + 15, y + 0, z + 16, Blocks.stonebrick, rand.nextInt(3), 3);
		WorldUtils.setBlock(world, x + 7, y + 1, z + 0, Blocks.air, 0, 3);
		WorldUtils.setBlock(world, x + 8, y + 1, z + 0, Blocks.air, 0, 3);
		WorldUtils.setBlock(world, x + 9, y + 1, z + 0, Blocks.air, 0, 3);
		WorldUtils.setBlock(world, x + 7, y + 1, z + 1, Blocks.air, 0, 3);
		WorldUtils.setBlock(world, x + 8, y + 1, z + 1, Blocks.air, 0, 3);
		WorldUtils.setBlock(world, x + 9, y + 1, z + 1, Blocks.air, 0, 3);
		WorldUtils.setBlock(world, x + 6, y + 1, z + 2, Blocks.air, 0, 3);
		WorldUtils.setBlock(world, x + 7, y + 1, z + 2, Blocks.air, 0, 3);
		WorldUtils.setBlock(world, x + 8, y + 1, z + 2, Blocks.air, 0, 3);
		WorldUtils.setBlock(world, x + 9, y + 1, z + 2, Blocks.air, 0, 3);
		WorldUtils.setBlock(world, x + 10, y + 1, z + 2, Blocks.air, 0, 3);
		WorldUtils.setBlock(world, x + 1, y + 1, z + 3, Blocks.stonebrick, rand.nextInt(3), 3);
		WorldUtils.setBlock(world, x + 2, y + 1, z + 3, Blocks.stonebrick, rand.nextInt(3), 3);
		WorldUtils.setBlock(world, x + 3, y + 1, z + 3, Blocks.stonebrick, rand.nextInt(3), 3);
		WorldUtils.setBlock(world, x + 4, y + 1, z + 3, Blocks.stonebrick, rand.nextInt(3), 3);
		WorldUtils.setBlock(world, x + 5, y + 1, z + 3, Blocks.stonebrick, rand.nextInt(3), 3);
		WorldUtils.setBlock(world, x + 6, y + 1, z + 3, Blocks.cobblestone_wall, rand.nextInt(2), 3);
		WorldUtils.setBlock(world, x + 7, y + 1, z + 3, Blocks.cobblestone_wall, rand.nextInt(2), 3);
		WorldUtils.setBlock(world, x + 8, y + 1, z + 3, Blocks.air, 0, 3);
		WorldUtils.setBlock(world, x + 9, y + 1, z + 3, Blocks.cobblestone_wall, rand.nextInt(2), 3);
		WorldUtils.setBlock(world, x + 10, y + 1, z + 3, Blocks.cobblestone_wall, rand.nextInt(2), 3);
		WorldUtils.setBlock(world, x + 11, y + 1, z + 3, Blocks.stonebrick, rand.nextInt(3), 3);
		WorldUtils.setBlock(world, x + 12, y + 1, z + 3, Blocks.stonebrick, rand.nextInt(3), 3);
		WorldUtils.setBlock(world, x + 13, y + 1, z + 3, Blocks.stonebrick, rand.nextInt(3), 3);
		WorldUtils.setBlock(world, x + 14, y + 1, z + 3, Blocks.stonebrick, rand.nextInt(3), 3);
		WorldUtils.setBlock(world, x + 15, y + 1, z + 3, Blocks.stonebrick, rand.nextInt(3), 3);
		WorldUtils.setBlock(world, x + 1, y + 1, z + 4, Blocks.stonebrick, rand.nextInt(3), 3);
		WorldUtils.setBlock(world, x + 2, y + 1, z + 4, Blocks.cobblestone_wall, rand.nextInt(2), 3);
		WorldUtils.setBlock(world, x + 3, y + 1, z + 4, Blocks.air, 0, 3);
		WorldUtils.setBlock(world, x + 4, y + 1, z + 4, Blocks.air, 0, 3);
		WorldUtils.setBlock(world, x + 5, y + 1, z + 4, Blocks.cobblestone_wall, rand.nextInt(2), 3);
		WorldUtils.setBlock(world, x + 6, y + 1, z + 4, Blocks.stonebrick, rand.nextInt(3), 3);
		WorldUtils.setBlock(world, x + 7, y + 1, z + 4, Blocks.air, 0, 3);
		WorldUtils.setBlock(world, x + 8, y + 1, z + 4, Blocks.air, 0, 3);
		WorldUtils.setBlock(world, x + 9, y + 1, z + 4, Blocks.air, 0, 3);
		WorldUtils.setBlock(world, x + 10, y + 1, z + 4, Blocks.stonebrick, rand.nextInt(3), 3);
		WorldUtils.setBlock(world, x + 11, y + 1, z + 4, Blocks.cobblestone_wall, rand.nextInt(2), 3);
		WorldUtils.setBlock(world, x + 12, y + 1, z + 4, Blocks.air, 0, 3);
		WorldUtils.setBlock(world, x + 13, y + 1, z + 4, Blocks.air, 0, 3);
		WorldUtils.setBlock(world, x + 14, y + 1, z + 4, Blocks.cobblestone_wall, rand.nextInt(2), 3);
		WorldUtils.setBlock(world, x + 15, y + 1, z + 4, Blocks.stonebrick, rand.nextInt(3), 3);
		WorldUtils.setBlock(world, x + 1, y + 1, z + 5, Blocks.stonebrick, rand.nextInt(3), 3);
		WorldUtils.setBlock(world, x + 2, y + 1, z + 5, Blocks.air, 0, 3);
		WorldUtils.setBlock(world, x + 3, y + 1, z + 5, Blocks.air, 0, 3);
		WorldUtils.setBlock(world, x + 4, y + 1, z + 5, Blocks.air, 0, 3);
		WorldUtils.setBlock(world, x + 5, y + 1, z + 5, Blocks.air, 0, 3);
		WorldUtils.setBlock(world, x + 6, y + 1, z + 5, Blocks.air, 0, 3);
		WorldUtils.setBlock(world, x + 7, y + 1, z + 5, Blocks.air, 0, 3);
		WorldUtils.setBlock(world, x + 8, y + 1, z + 5, Blocks.air, 0, 3);
		WorldUtils.setBlock(world, x + 9, y + 1, z + 5, Blocks.air, 0, 3);
		WorldUtils.setBlock(world, x + 10, y + 1, z + 5, Blocks.air, 0, 3);
		WorldUtils.setBlock(world, x + 11, y + 1, z + 5, Blocks.air, 0, 3);
		WorldUtils.setBlock(world, x + 12, y + 1, z + 5, Blocks.air, 0, 3);
		WorldUtils.setBlock(world, x + 13, y + 1, z + 5, Blocks.air, 0, 3);
		WorldUtils.setBlock(world, x + 14, y + 1, z + 5, Blocks.air, 0, 3);
		WorldUtils.setBlock(world, x + 15, y + 1, z + 5, Blocks.stonebrick, rand.nextInt(3), 3);
		WorldUtils.setBlock(world, x + 1, y + 1, z + 6, Blocks.stonebrick, rand.nextInt(3), 3);
		WorldUtils.setBlock(world, x + 2, y + 1, z + 6, Blocks.air, 0, 3);
		WorldUtils.setBlock(world, x + 3, y + 1, z + 6, Blocks.air, 0, 3);
		WorldUtils.setBlock(world, x + 4, y + 1, z + 6, Blocks.air, 0, 3);
		WorldUtils.setBlock(world, x + 5, y + 1, z + 6, Blocks.air, 0, 3);
		WorldUtils.setBlock(world, x + 6, y + 1, z + 6, Blocks.air, 0, 3);
		WorldUtils.setBlock(world, x + 7, y + 1, z + 6, Blocks.air, 0, 3);
		WorldUtils.setBlock(world, x + 8, y + 1, z + 6, Blocks.air, 0, 3);
		WorldUtils.setBlock(world, x + 9, y + 1, z + 6, Blocks.air, 0, 3);
		WorldUtils.setBlock(world, x + 10, y + 1, z + 6, Blocks.air, 0, 3);
		WorldUtils.setBlock(world, x + 11, y + 1, z + 6, Blocks.air, 0, 3);
		WorldUtils.setBlock(world, x + 12, y + 1, z + 6, Blocks.air, 0, 3);
		WorldUtils.setBlock(world, x + 13, y + 1, z + 6, Blocks.air, 0, 3);
		WorldUtils.setBlock(world, x + 14, y + 1, z + 6, Blocks.air, 0, 3);
		WorldUtils.setBlock(world, x + 15, y + 1, z + 6, Blocks.stonebrick, rand.nextInt(3), 3);
		WorldUtils.setBlock(world, x + 1, y + 1, z + 7, Blocks.stonebrick, rand.nextInt(3), 3);
		WorldUtils.setBlock(world, x + 2, y + 1, z + 7, Blocks.cobblestone_wall, rand.nextInt(2), 3);
		WorldUtils.setBlock(world, x + 3, y + 1, z + 7, Blocks.air, 0, 3);
		WorldUtils.setBlock(world, x + 4, y + 1, z + 7, Blocks.air, 0, 3);
		WorldUtils.setBlock(world, x + 5, y + 1, z + 7, Blocks.air, 0, 3);
		WorldUtils.setBlock(world, x + 6, y + 1, z + 7, Blocks.air, 0, 3);
		WorldUtils.setBlock(world, x + 7, y + 1, z + 7, Blocks.air, 0, 3);
		WorldUtils.setBlock(world, x + 8, y + 1, z + 7, Blocks.air, 0, 3);
		WorldUtils.setBlock(world, x + 9, y + 1, z + 7, Blocks.air, 0, 3);
		WorldUtils.setBlock(world, x + 10, y + 1, z + 7, Blocks.air, 0, 3);
		WorldUtils.setBlock(world, x + 11, y + 1, z + 7, Blocks.air, 0, 3);
		WorldUtils.setBlock(world, x + 12, y + 1, z + 7, Blocks.air, 0, 3);
		WorldUtils.setBlock(world, x + 13, y + 1, z + 7, Blocks.air, 0, 3);
		WorldUtils.setBlock(world, x + 14, y + 1, z + 7, Blocks.cobblestone_wall, rand.nextInt(2), 3);
		WorldUtils.setBlock(world, x + 15, y + 1, z + 7, Blocks.stonebrick, rand.nextInt(3), 3);
		WorldUtils.setBlock(world, x + 1, y + 1, z + 8, Blocks.stonebrick, rand.nextInt(3), 3);
		WorldUtils.setBlock(world, x + 2, y + 1, z + 8, Blocks.air, 0, 3);
		WorldUtils.setBlock(world, x + 3, y + 1, z + 8, Blocks.air, 0, 3);
		WorldUtils.setBlock(world, x + 4, y + 1, z + 8, Blocks.air, 0, 3);
		WorldUtils.setBlock(world, x + 5, y + 1, z + 8, Blocks.air, 0, 3);
		WorldUtils.setBlock(world, x + 6, y + 1, z + 8, Blocks.air, 0, 3);
		WorldUtils.setBlock(world, x + 7, y + 1, z + 8, Blocks.air, 0, 3);
		WorldUtils.setBlock(world, x + 8, y + 1, z + 8, Blocks.air, 0, 3);
		WorldUtils.setBlock(world, x + 9, y + 1, z + 8, Blocks.air, 0, 3);
		WorldUtils.setBlock(world, x + 10, y + 1, z + 8, Blocks.air, 0, 3);
		WorldUtils.setBlock(world, x + 11, y + 1, z + 8, Blocks.air, 0, 3);
		WorldUtils.setBlock(world, x + 12, y + 1, z + 8, Blocks.air, 0, 3);
		WorldUtils.setBlock(world, x + 13, y + 1, z + 8, Blocks.air, 0, 3);
		WorldUtils.setBlock(world, x + 14, y + 1, z + 8, Blocks.air, 0, 3);
		WorldUtils.setBlock(world, x + 15, y + 1, z + 8, Blocks.stonebrick, rand.nextInt(3), 3);
		WorldUtils.setBlock(world, x + 1, y + 1, z + 9, Blocks.stonebrick, rand.nextInt(3), 3);
		WorldUtils.setBlock(world, x + 2, y + 1, z + 9, Blocks.air, 0, 3);
		WorldUtils.setBlock(world, x + 3, y + 1, z + 9, Blocks.air, 0, 3);
		WorldUtils.setBlock(world, x + 4, y + 1, z + 9, Blocks.air, 0, 3);
		WorldUtils.setBlock(world, x + 5, y + 1, z + 9, Blocks.air, 0, 3);
		WorldUtils.setBlock(world, x + 6, y + 1, z + 9, Blocks.air, 0, 3);
		WorldUtils.setBlock(world, x + 7, y + 1, z + 9, Blocks.air, 0, 3);
		WorldUtils.setBlock(world, x + 8, y + 1, z + 9, Blocks.air, 0, 3);
		WorldUtils.setBlock(world, x + 9, y + 1, z + 9, Blocks.air, 0, 3);
		WorldUtils.setBlock(world, x + 10, y + 1, z + 9, Blocks.air, 0, 3);
		WorldUtils.setBlock(world, x + 11, y + 1, z + 9, Blocks.air, 0, 3);
		WorldUtils.setBlock(world, x + 12, y + 1, z + 9, Blocks.air, 0, 3);
		WorldUtils.setBlock(world, x + 13, y + 1, z + 9, Blocks.air, 0, 3);
		WorldUtils.setBlock(world, x + 14, y + 1, z + 9, Blocks.air, 0, 3);
		WorldUtils.setBlock(world, x + 15, y + 1, z + 9, Blocks.stonebrick, rand.nextInt(3), 3);
		WorldUtils.setBlock(world, x + 1, y + 1, z + 10, Blocks.stonebrick, rand.nextInt(3), 3);
		WorldUtils.setBlock(world, x + 2, y + 1, z + 10, Blocks.air, 0, 3);
		WorldUtils.setBlock(world, x + 3, y + 1, z + 10, Blocks.air, 0, 3);
		WorldUtils.setBlock(world, x + 4, y + 1, z + 10, Blocks.air, 0, 3);
		WorldUtils.setBlock(world, x + 5, y + 1, z + 10, Blocks.air, 0, 3);
		WorldUtils.setBlock(world, x + 6, y + 1, z + 10, Blocks.air, 0, 3);
		WorldUtils.setBlock(world, x + 7, y + 1, z + 10, Blocks.air, 0, 3);
		WorldUtils.setBlock(world, x + 8, y + 1, z + 10, Blocks.air, 0, 3);
		WorldUtils.setBlock(world, x + 9, y + 1, z + 10, Blocks.air, 0, 3);
		WorldUtils.setBlock(world, x + 10, y + 1, z + 10, Blocks.air, 0, 3);
		WorldUtils.setBlock(world, x + 11, y + 1, z + 10, Blocks.air, 0, 3);
		WorldUtils.setBlock(world, x + 12, y + 1, z + 10, Blocks.air, 0, 3);
		WorldUtils.setBlock(world, x + 13, y + 1, z + 10, Blocks.air, 0, 3);
		WorldUtils.setBlock(world, x + 14, y + 1, z + 10, Blocks.air, 0, 3);
		WorldUtils.setBlock(world, x + 15, y + 1, z + 10, Blocks.stonebrick, rand.nextInt(3), 3);
		WorldUtils.setBlock(world, x + 1, y + 1, z + 11, Blocks.stonebrick, rand.nextInt(3), 3);
		WorldUtils.setBlock(world, x + 2, y + 1, z + 11, Blocks.air, 0, 3);
		WorldUtils.setBlock(world, x + 3, y + 1, z + 11, Blocks.air, 0, 3);
		WorldUtils.setBlock(world, x + 4, y + 1, z + 11, Blocks.air, 0, 3);
		WorldUtils.setBlock(world, x + 5, y + 1, z + 11, Blocks.air, 0, 3);
		WorldUtils.setBlock(world, x + 6, y + 1, z + 11, Blocks.air, 0, 3);
		WorldUtils.setBlock(world, x + 7, y + 1, z + 11, Blocks.air, 0, 3);
		WorldUtils.setBlock(world, x + 8, y + 1, z + 11, Blocks.air, 0, 3);
		WorldUtils.setBlock(world, x + 9, y + 1, z + 11, Blocks.air, 0, 3);
		WorldUtils.setBlock(world, x + 10, y + 1, z + 11, Blocks.air, 0, 3);
		WorldUtils.setBlock(world, x + 11, y + 1, z + 11, Blocks.air, 0, 3);
		WorldUtils.setBlock(world, x + 12, y + 1, z + 11, Blocks.air, 0, 3);
		WorldUtils.setBlock(world, x + 13, y + 1, z + 11, Blocks.air, 0, 3);
		WorldUtils.setBlock(world, x + 14, y + 1, z + 11, Blocks.air, 0, 3);
		WorldUtils.setBlock(world, x + 15, y + 1, z + 11, Blocks.stonebrick, rand.nextInt(3), 3);
		WorldUtils.setBlock(world, x + 1, y + 1, z + 12, Blocks.stonebrick, rand.nextInt(3), 3);
		WorldUtils.setBlock(world, x + 2, y + 1, z + 12, Blocks.cobblestone_wall, rand.nextInt(2), 3);
		WorldUtils.setBlock(world, x + 3, y + 1, z + 12, Blocks.air, 0, 3);
		WorldUtils.setBlock(world, x + 4, y + 1, z + 12, Blocks.air, 0, 3);
		WorldUtils.setBlock(world, x + 5, y + 1, z + 12, Blocks.air, 0, 3);
		WorldUtils.setBlock(world, x + 6, y + 1, z + 12, Blocks.stone_brick_stairs, 0, 3);
		WorldUtils.setBlock(world, x + 7, y + 1, z + 12, Blocks.stone_brick_stairs, 2, 3);
		WorldUtils.setBlock(world, x + 8, y + 1, z + 12, Blocks.stone_brick_stairs, 2, 3);
		WorldUtils.setBlock(world, x + 9, y + 1, z + 12, Blocks.stone_brick_stairs, 2, 3);
		WorldUtils.setBlock(world, x + 10, y + 1, z + 12, Blocks.stone_brick_stairs, 1, 3);
		WorldUtils.setBlock(world, x + 11, y + 1, z + 12, Blocks.air, 0, 3);
		WorldUtils.setBlock(world, x + 12, y + 1, z + 12, Blocks.air, 0, 3);
		WorldUtils.setBlock(world, x + 13, y + 1, z + 12, Blocks.air, 0, 3);
		WorldUtils.setBlock(world, x + 14, y + 1, z + 12, Blocks.cobblestone_wall, rand.nextInt(2), 3);
		WorldUtils.setBlock(world, x + 15, y + 1, z + 12, Blocks.stonebrick, rand.nextInt(3), 3);
		WorldUtils.setBlock(world, x + 1, y + 1, z + 13, Blocks.stonebrick, rand.nextInt(3), 3);
		WorldUtils.setBlock(world, x + 2, y + 1, z + 13, Blocks.air, 0, 3);
		WorldUtils.setBlock(world, x + 3, y + 1, z + 13, Blocks.air, 0, 3);
		WorldUtils.setBlock(world, x + 4, y + 1, z + 13, Blocks.pumpkin, 3, 3);
		WorldUtils.setBlock(world, x + 5, y + 1, z + 13, Blocks.air, 0, 3);
		WorldUtils.setBlock(world, x + 6, y + 1, z + 13, Blocks.stone_brick_stairs, 0, 3);
		WorldUtils.setBlock(world, x + 7, y + 1, z + 13, Blocks.stonebrick, rand.nextInt(3), 3);
		WorldUtils.setBlock(world, x + 8, y + 1, z + 13, Blocks.stonebrick, rand.nextInt(3), 3);
		WorldUtils.setBlock(world, x + 9, y + 1, z + 13, Blocks.stonebrick, rand.nextInt(3), 3);
		WorldUtils.setBlock(world, x + 10, y + 1, z + 13, Blocks.stone_brick_stairs, 1, 3);
		WorldUtils.setBlock(world, x + 11, y + 1, z + 13, Blocks.air, 0, 3);
		WorldUtils.setBlock(world, x + 12, y + 1, z + 13, Blocks.pumpkin, 1, 3);
		WorldUtils.setBlock(world, x + 13, y + 1, z + 13, Blocks.air, 0, 3);
		WorldUtils.setBlock(world, x + 14, y + 1, z + 13, Blocks.air, 0, 3);
		WorldUtils.setBlock(world, x + 15, y + 1, z + 13, Blocks.stonebrick, rand.nextInt(3), 3);
		WorldUtils.setBlock(world, x + 1, y + 1, z + 14, Blocks.stonebrick, rand.nextInt(3), 3);
		WorldUtils.setBlock(world, x + 2, y + 1, z + 14, Blocks.air, 0, 3);
		WorldUtils.setBlock(world, x + 3, y + 1, z + 14, Blocks.air, 0, 3);
		WorldUtils.setBlock(world, x + 4, y + 1, z + 14, Blocks.air, 0, 3);
		WorldUtils.setBlock(world, x + 5, y + 1, z + 14, Blocks.air, 0, 3);
		WorldUtils.setBlock(world, x + 6, y + 1, z + 14, Blocks.stone_brick_stairs, 3, 3);
		WorldUtils.setBlock(world, x + 7, y + 1, z + 14, Blocks.stone_brick_stairs, 3, 3);
		WorldUtils.setBlock(world, x + 8, y + 1, z + 14, Blocks.stone_brick_stairs, 3, 3);
		WorldUtils.setBlock(world, x + 9, y + 1, z + 14, Blocks.stone_brick_stairs, 3, 3);
		WorldUtils.setBlock(world, x + 10, y + 1, z + 14, Blocks.stone_brick_stairs, 1, 3);
		WorldUtils.setBlock(world, x + 11, y + 1, z + 14, Blocks.air, 0, 3);
		WorldUtils.setBlock(world, x + 12, y + 1, z + 14, Blocks.air, 0, 3);
		WorldUtils.setBlock(world, x + 13, y + 1, z + 14, Blocks.air, 0, 3);
		WorldUtils.setBlock(world, x + 14, y + 1, z + 14, Blocks.air, 0, 3);
		WorldUtils.setBlock(world, x + 15, y + 1, z + 14, Blocks.stonebrick, rand.nextInt(3), 3);
		WorldUtils.setBlock(world, x + 1, y + 1, z + 15, Blocks.stonebrick, rand.nextInt(3), 3);
		WorldUtils.setBlock(world, x + 2, y + 1, z + 15, Blocks.cobblestone_wall, rand.nextInt(2), 3);
		WorldUtils.setBlock(world, x + 3, y + 1, z + 15, Blocks.air, 0, 3);
		WorldUtils.setBlock(world, x + 4, y + 1, z + 15, Blocks.air, 0, 3);
		WorldUtils.setBlock(world, x + 5, y + 1, z + 15, Blocks.cobblestone_wall, rand.nextInt(2), 3);
		WorldUtils.setBlock(world, x + 6, y + 1, z + 15, Blocks.air, 0, 3);
		WorldUtils.setBlock(world, x + 7, y + 1, z + 15, Blocks.air, 0, 3);
		WorldUtils.setBlock(world, x + 8, y + 1, z + 15, Blocks.air, 0, 3);
		WorldUtils.setBlock(world, x + 9, y + 1, z + 15, Blocks.air, 0, 3);
		WorldUtils.setBlock(world, x + 10, y + 1, z + 15, Blocks.air, 0, 3);
		WorldUtils.setBlock(world, x + 11, y + 1, z + 15, Blocks.cobblestone_wall, rand.nextInt(2), 3);
		WorldUtils.setBlock(world, x + 12, y + 1, z + 15, Blocks.air, 0, 3);
		WorldUtils.setBlock(world, x + 13, y + 1, z + 15, Blocks.air, 0, 3);
		WorldUtils.setBlock(world, x + 14, y + 1, z + 15, Blocks.cobblestone_wall, rand.nextInt(2), 3);
		WorldUtils.setBlock(world, x + 15, y + 1, z + 15, Blocks.stonebrick, rand.nextInt(3), 3);
		WorldUtils.setBlock(world, x + 1, y + 1, z + 16, Blocks.stonebrick, rand.nextInt(3), 3);
		WorldUtils.setBlock(world, x + 2, y + 1, z + 16, Blocks.stonebrick, rand.nextInt(3), 3);
		WorldUtils.setBlock(world, x + 3, y + 1, z + 16, Blocks.stonebrick, rand.nextInt(3), 3);
		WorldUtils.setBlock(world, x + 4, y + 1, z + 16, Blocks.stonebrick, rand.nextInt(3), 3);
		WorldUtils.setBlock(world, x + 5, y + 1, z + 16, Blocks.stonebrick, rand.nextInt(3), 3);
		WorldUtils.setBlock(world, x + 6, y + 1, z + 16, Blocks.stonebrick, rand.nextInt(3), 3);
		WorldUtils.setBlock(world, x + 7, y + 1, z + 16, Blocks.stonebrick, rand.nextInt(3), 3);
		WorldUtils.setBlock(world, x + 8, y + 1, z + 16, Blocks.stonebrick, rand.nextInt(3), 3);
		WorldUtils.setBlock(world, x + 9, y + 1, z + 16, Blocks.stonebrick, rand.nextInt(3), 3);
		WorldUtils.setBlock(world, x + 10, y + 1, z + 16, Blocks.stonebrick, rand.nextInt(3), 3);
		WorldUtils.setBlock(world, x + 11, y + 1, z + 16, Blocks.stonebrick, rand.nextInt(3), 3);
		WorldUtils.setBlock(world, x + 12, y + 1, z + 16, Blocks.stonebrick, rand.nextInt(3), 3);
		WorldUtils.setBlock(world, x + 13, y + 1, z + 16, Blocks.stonebrick, rand.nextInt(3), 3);
		WorldUtils.setBlock(world, x + 14, y + 1, z + 16, Blocks.stonebrick, rand.nextInt(3), 3);
		WorldUtils.setBlock(world, x + 15, y + 1, z + 16, Blocks.stonebrick, rand.nextInt(3), 3);
		WorldUtils.setBlock(world, x + 7, y + 2, z + 0, Blocks.air, 0, 3);
		WorldUtils.setBlock(world, x + 8, y + 2, z + 0, Blocks.air, 0, 3);
		WorldUtils.setBlock(world, x + 9, y + 2, z + 0, Blocks.air, 0, 3);
		WorldUtils.setBlock(world, x + 7, y + 2, z + 1, Blocks.air, 0, 3);
		WorldUtils.setBlock(world, x + 8, y + 2, z + 1, Blocks.air, 0, 3);
		WorldUtils.setBlock(world, x + 9, y + 2, z + 1, Blocks.air, 0, 3);
		WorldUtils.setBlock(world, x + 3, y + 2, z + 2, Blocks.air, 0, 3);
		WorldUtils.setBlock(world, x + 4, y + 2, z + 2, Blocks.air, 0, 3);
		WorldUtils.setBlock(world, x + 6, y + 2, z + 2, Blocks.air, 0, 3);
		WorldUtils.setBlock(world, x + 7, y + 2, z + 2, Blocks.air, 0, 3);
		WorldUtils.setBlock(world, x + 8, y + 2, z + 2, Blocks.air, 0, 3);
		WorldUtils.setBlock(world, x + 9, y + 2, z + 2, Blocks.air, 0, 3);
		WorldUtils.setBlock(world, x + 10, y + 2, z + 2, Blocks.air, 0, 3);
		WorldUtils.setBlock(world, x + 12, y + 2, z + 2, Blocks.air, 0, 3);
		WorldUtils.setBlock(world, x + 13, y + 2, z + 2, Blocks.air, 0, 3);
		WorldUtils.setBlock(world, x + 1, y + 2, z + 3, Blocks.stonebrick, rand.nextInt(3), 3);
		WorldUtils.setBlock(world, x + 2, y + 2, z + 3, Blocks.stonebrick, rand.nextInt(3), 3);
		WorldUtils.setBlock(world, x + 3, y + 2, z + 3, Blocks.iron_bars, 0, 3);
		WorldUtils.setBlock(world, x + 4, y + 2, z + 3, Blocks.iron_bars, 0, 3);
		WorldUtils.setBlock(world, x + 5, y + 2, z + 3, Blocks.stonebrick, rand.nextInt(3), 3);
		WorldUtils.setBlock(world, x + 6, y + 2, z + 3, Blocks.cobblestone_wall, rand.nextInt(2), 3);
		WorldUtils.setBlock(world, x + 7, y + 2, z + 3, Blocks.air, 0, 3);
		WorldUtils.setBlock(world, x + 8, y + 2, z + 3, Blocks.air, 0, 3);
		WorldUtils.setBlock(world, x + 9, y + 2, z + 3, Blocks.air, 0, 3);
		WorldUtils.setBlock(world, x + 10, y + 2, z + 3, Blocks.cobblestone_wall, rand.nextInt(2), 3);
		WorldUtils.setBlock(world, x + 11, y + 2, z + 3, Blocks.stonebrick, rand.nextInt(3), 3);
		WorldUtils.setBlock(world, x + 12, y + 2, z + 3, Blocks.iron_bars, 0, 3);
		WorldUtils.setBlock(world, x + 13, y + 2, z + 3, Blocks.iron_bars, 0, 3);
		WorldUtils.setBlock(world, x + 14, y + 2, z + 3, Blocks.stonebrick, rand.nextInt(3), 3);
		WorldUtils.setBlock(world, x + 15, y + 2, z + 3, Blocks.stonebrick, rand.nextInt(3), 3);
		WorldUtils.setBlock(world, x + 1, y + 2, z + 4, Blocks.stonebrick, rand.nextInt(3), 3);
		WorldUtils.setBlock(world, x + 2, y + 2, z + 4, Blocks.cobblestone_wall, rand.nextInt(2), 3);
		WorldUtils.setBlock(world, x + 3, y + 2, z + 4, Blocks.air, 0, 3);
		WorldUtils.setBlock(world, x + 4, y + 2, z + 4, Blocks.air, 0, 3);
		WorldUtils.setBlock(world, x + 5, y + 2, z + 4, Blocks.cobblestone_wall, rand.nextInt(2), 3);
		WorldUtils.setBlock(world, x + 6, y + 2, z + 4, Blocks.stonebrick, rand.nextInt(3), 3);
		WorldUtils.setBlock(world, x + 7, y + 2, z + 4, Blocks.air, 0, 3);
		WorldUtils.setBlock(world, x + 8, y + 2, z + 4, Blocks.air, 0, 3);
		WorldUtils.setBlock(world, x + 9, y + 2, z + 4, Blocks.air, 0, 3);
		WorldUtils.setBlock(world, x + 10, y + 2, z + 4, Blocks.stonebrick, rand.nextInt(3), 3);
		WorldUtils.setBlock(world, x + 11, y + 2, z + 4, Blocks.cobblestone_wall, rand.nextInt(2), 3);
		WorldUtils.setBlock(world, x + 12, y + 2, z + 4, Blocks.air, 0, 3);
		WorldUtils.setBlock(world, x + 13, y + 2, z + 4, Blocks.air, 0, 3);
		WorldUtils.setBlock(world, x + 14, y + 2, z + 4, Blocks.cobblestone_wall, rand.nextInt(2), 3);
		WorldUtils.setBlock(world, x + 15, y + 2, z + 4, Blocks.stonebrick, rand.nextInt(3), 3);
		WorldUtils.setBlock(world, x + 0, y + 2, z + 5, Blocks.air, 0, 3);
		WorldUtils.setBlock(world, x + 1, y + 2, z + 5, Blocks.iron_bars, 0, 3);
		WorldUtils.setBlock(world, x + 2, y + 2, z + 5, Blocks.air, 0, 3);
		WorldUtils.setBlock(world, x + 3, y + 2, z + 5, Blocks.air, 0, 3);
		WorldUtils.setBlock(world, x + 4, y + 2, z + 5, Blocks.air, 0, 3);
		WorldUtils.setBlock(world, x + 5, y + 2, z + 5, Blocks.air, 0, 3);
		WorldUtils.setBlock(world, x + 6, y + 2, z + 5, Blocks.air, 0, 3);
		WorldUtils.setBlock(world, x + 7, y + 2, z + 5, Blocks.air, 0, 3);
		WorldUtils.setBlock(world, x + 8, y + 2, z + 5, Blocks.air, 0, 3);
		WorldUtils.setBlock(world, x + 9, y + 2, z + 5, Blocks.air, 0, 3);
		WorldUtils.setBlock(world, x + 10, y + 2, z + 5, Blocks.air, 0, 3);
		WorldUtils.setBlock(world, x + 11, y + 2, z + 5, Blocks.air, 0, 3);
		WorldUtils.setBlock(world, x + 12, y + 2, z + 5, Blocks.air, 0, 3);
		WorldUtils.setBlock(world, x + 13, y + 2, z + 5, Blocks.air, 0, 3);
		WorldUtils.setBlock(world, x + 14, y + 2, z + 5, Blocks.air, 0, 3);
		WorldUtils.setBlock(world, x + 15, y + 2, z + 5, Blocks.iron_bars, 0, 3);
		WorldUtils.setBlock(world, x + 16, y + 2, z + 5, Blocks.air, 0, 3);
		WorldUtils.setBlock(world, x + 0, y + 2, z + 6, Blocks.air, 0, 3);
		WorldUtils.setBlock(world, x + 1, y + 2, z + 6, Blocks.iron_bars, 0, 3);
		WorldUtils.setBlock(world, x + 2, y + 2, z + 6, Blocks.air, 0, 3);
		WorldUtils.setBlock(world, x + 3, y + 2, z + 6, Blocks.air, 0, 3);
		WorldUtils.setBlock(world, x + 4, y + 2, z + 6, Blocks.air, 0, 3);
		WorldUtils.setBlock(world, x + 5, y + 2, z + 6, Blocks.air, 0, 3);
		WorldUtils.setBlock(world, x + 6, y + 2, z + 6, Blocks.air, 0, 3);
		WorldUtils.setBlock(world, x + 7, y + 2, z + 6, Blocks.air, 0, 3);
		WorldUtils.setBlock(world, x + 8, y + 2, z + 6, Blocks.air, 0, 3);
		WorldUtils.setBlock(world, x + 9, y + 2, z + 6, Blocks.air, 0, 3);
		WorldUtils.setBlock(world, x + 10, y + 2, z + 6, Blocks.air, 0, 3);
		WorldUtils.setBlock(world, x + 11, y + 2, z + 6, Blocks.air, 0, 3);
		WorldUtils.setBlock(world, x + 12, y + 2, z + 6, Blocks.air, 0, 3);
		WorldUtils.setBlock(world, x + 13, y + 2, z + 6, Blocks.air, 0, 3);
		WorldUtils.setBlock(world, x + 14, y + 2, z + 6, Blocks.air, 0, 3);
		WorldUtils.setBlock(world, x + 15, y + 2, z + 6, Blocks.iron_bars, 0, 3);
		WorldUtils.setBlock(world, x + 16, y + 2, z + 6, Blocks.air, 0, 3);
		WorldUtils.setBlock(world, x + 1, y + 2, z + 7, Blocks.stonebrick, rand.nextInt(3), 3);
		WorldUtils.setBlock(world, x + 2, y + 2, z + 7, Blocks.cobblestone_wall, rand.nextInt(2), 3);
		WorldUtils.setBlock(world, x + 3, y + 2, z + 7, Blocks.air, 0, 3);
		WorldUtils.setBlock(world, x + 4, y + 2, z + 7, Blocks.air, 0, 3);
		WorldUtils.setBlock(world, x + 5, y + 2, z + 7, Blocks.air, 0, 3);
		WorldUtils.setBlock(world, x + 6, y + 2, z + 7, Blocks.air, 0, 3);
		WorldUtils.setBlock(world, x + 7, y + 2, z + 7, Blocks.air, 0, 3);
		WorldUtils.setBlock(world, x + 8, y + 2, z + 7, Blocks.air, 0, 3);
		WorldUtils.setBlock(world, x + 9, y + 2, z + 7, Blocks.air, 0, 3);
		WorldUtils.setBlock(world, x + 10, y + 2, z + 7, Blocks.air, 0, 3);
		WorldUtils.setBlock(world, x + 11, y + 2, z + 7, Blocks.air, 0, 3);
		WorldUtils.setBlock(world, x + 12, y + 2, z + 7, Blocks.air, 0, 3);
		WorldUtils.setBlock(world, x + 13, y + 2, z + 7, Blocks.air, 0, 3);
		WorldUtils.setBlock(world, x + 14, y + 2, z + 7, Blocks.cobblestone_wall, rand.nextInt(2), 3);
		WorldUtils.setBlock(world, x + 15, y + 2, z + 7, Blocks.stonebrick, rand.nextInt(3), 3);
		WorldUtils.setBlock(world, x + 0, y + 2, z + 8, Blocks.air, 0, 3);
		WorldUtils.setBlock(world, x + 1, y + 2, z + 8, Blocks.iron_bars, 0, 3);
		WorldUtils.setBlock(world, x + 2, y + 2, z + 8, Blocks.air, 0, 3);
		WorldUtils.setBlock(world, x + 3, y + 2, z + 8, Blocks.air, 0, 3);
		WorldUtils.setBlock(world, x + 4, y + 2, z + 8, Blocks.air, 0, 3);
		WorldUtils.setBlock(world, x + 5, y + 2, z + 8, Blocks.air, 0, 3);
		WorldUtils.setBlock(world, x + 6, y + 2, z + 8, Blocks.air, 0, 3);
		WorldUtils.setBlock(world, x + 7, y + 2, z + 8, Blocks.air, 0, 3);
		WorldUtils.setBlock(world, x + 8, y + 2, z + 8, Blocks.air, 0, 3);
		WorldUtils.setBlock(world, x + 9, y + 2, z + 8, Blocks.air, 0, 3);
		WorldUtils.setBlock(world, x + 10, y + 2, z + 8, Blocks.air, 0, 3);
		WorldUtils.setBlock(world, x + 11, y + 2, z + 8, Blocks.air, 0, 3);
		WorldUtils.setBlock(world, x + 12, y + 2, z + 8, Blocks.air, 0, 3);
		WorldUtils.setBlock(world, x + 13, y + 2, z + 8, Blocks.air, 0, 3);
		WorldUtils.setBlock(world, x + 14, y + 2, z + 8, Blocks.air, 0, 3);
		WorldUtils.setBlock(world, x + 15, y + 2, z + 8, Blocks.iron_bars, 0, 3);
		WorldUtils.setBlock(world, x + 16, y + 2, z + 8, Blocks.air, 0, 3);
		WorldUtils.setBlock(world, x + 1, y + 2, z + 9, Blocks.stonebrick, rand.nextInt(3), 3);
		WorldUtils.setBlock(world, x + 2, y + 2, z + 9, Blocks.air, 0, 3);
		WorldUtils.setBlock(world, x + 3, y + 2, z + 9, Blocks.air, 0, 3);
		WorldUtils.setBlock(world, x + 4, y + 2, z + 9, Blocks.air, 0, 3);
		WorldUtils.setBlock(world, x + 5, y + 2, z + 9, Blocks.air, 0, 3);
		WorldUtils.setBlock(world, x + 6, y + 2, z + 9, Blocks.air, 0, 3);
		WorldUtils.setBlock(world, x + 7, y + 2, z + 9, Blocks.air, 0, 3);
		WorldUtils.setBlock(world, x + 8, y + 2, z + 9, Blocks.air, 0, 3);
		WorldUtils.setBlock(world, x + 9, y + 2, z + 9, Blocks.air, 0, 3);
		WorldUtils.setBlock(world, x + 10, y + 2, z + 9, Blocks.air, 0, 3);
		WorldUtils.setBlock(world, x + 11, y + 2, z + 9, Blocks.air, 0, 3);
		WorldUtils.setBlock(world, x + 12, y + 2, z + 9, Blocks.air, 0, 3);
		WorldUtils.setBlock(world, x + 13, y + 2, z + 9, Blocks.air, 0, 3);
		WorldUtils.setBlock(world, x + 14, y + 2, z + 9, Blocks.air, 0, 3);
		WorldUtils.setBlock(world, x + 15, y + 2, z + 9, Blocks.stonebrick, rand.nextInt(3), 3);
		WorldUtils.setBlock(world, x + 1, y + 2, z + 10, Blocks.stonebrick, rand.nextInt(3), 3);
		WorldUtils.setBlock(world, x + 2, y + 2, z + 10, Blocks.air, 0, 3);
		WorldUtils.setBlock(world, x + 3, y + 2, z + 10, Blocks.air, 0, 3);
		WorldUtils.setBlock(world, x + 4, y + 2, z + 10, Blocks.air, 0, 3);
		WorldUtils.setBlock(world, x + 5, y + 2, z + 10, Blocks.air, 0, 3);
		WorldUtils.setBlock(world, x + 6, y + 2, z + 10, Blocks.air, 0, 3);
		WorldUtils.setBlock(world, x + 7, y + 2, z + 10, Blocks.air, 0, 3);
		WorldUtils.setBlock(world, x + 8, y + 2, z + 10, Blocks.air, 0, 3);
		WorldUtils.setBlock(world, x + 9, y + 2, z + 10, Blocks.air, 0, 3);
		WorldUtils.setBlock(world, x + 10, y + 2, z + 10, Blocks.air, 0, 3);
		WorldUtils.setBlock(world, x + 11, y + 2, z + 10, Blocks.air, 0, 3);
		WorldUtils.setBlock(world, x + 12, y + 2, z + 10, Blocks.air, 0, 3);
		WorldUtils.setBlock(world, x + 13, y + 2, z + 10, Blocks.air, 0, 3);
		WorldUtils.setBlock(world, x + 14, y + 2, z + 10, Blocks.air, 0, 3);
		WorldUtils.setBlock(world, x + 15, y + 2, z + 10, Blocks.stonebrick, rand.nextInt(3), 3);
		WorldUtils.setBlock(world, x + 0, y + 2, z + 11, Blocks.air, 0, 3);
		WorldUtils.setBlock(world, x + 1, y + 2, z + 11, Blocks.iron_bars, 0, 3);
		WorldUtils.setBlock(world, x + 2, y + 2, z + 11, Blocks.air, 0, 3);
		WorldUtils.setBlock(world, x + 3, y + 2, z + 11, Blocks.air, 0, 3);
		WorldUtils.setBlock(world, x + 4, y + 2, z + 11, Blocks.air, 0, 3);
		WorldUtils.setBlock(world, x + 5, y + 2, z + 11, Blocks.air, 0, 3);
		WorldUtils.setBlock(world, x + 6, y + 2, z + 11, Blocks.air, 0, 3);
		WorldUtils.setBlock(world, x + 7, y + 2, z + 11, Blocks.air, 0, 3);
		WorldUtils.setBlock(world, x + 8, y + 2, z + 11, Blocks.air, 0, 3);
		WorldUtils.setBlock(world, x + 9, y + 2, z + 11, Blocks.air, 0, 3);
		WorldUtils.setBlock(world, x + 10, y + 2, z + 11, Blocks.air, 0, 3);
		WorldUtils.setBlock(world, x + 11, y + 2, z + 11, Blocks.air, 0, 3);
		WorldUtils.setBlock(world, x + 12, y + 2, z + 11, Blocks.air, 0, 3);
		WorldUtils.setBlock(world, x + 13, y + 2, z + 11, Blocks.air, 0, 3);
		WorldUtils.setBlock(world, x + 14, y + 2, z + 11, Blocks.air, 0, 3);
		WorldUtils.setBlock(world, x + 15, y + 2, z + 11, Blocks.iron_bars, 0, 3);
		WorldUtils.setBlock(world, x + 16, y + 2, z + 11, Blocks.air, 0, 3);
		WorldUtils.setBlock(world, x + 1, y + 2, z + 12, Blocks.stonebrick, rand.nextInt(3), 3);
		WorldUtils.setBlock(world, x + 2, y + 2, z + 12, Blocks.cobblestone_wall, rand.nextInt(2), 3);
		WorldUtils.setBlock(world, x + 3, y + 2, z + 12, Blocks.air, 0, 3);
		WorldUtils.setBlock(world, x + 4, y + 2, z + 12, Blocks.air, 0, 3);
		WorldUtils.setBlock(world, x + 5, y + 2, z + 12, Blocks.air, 0, 3);
		WorldUtils.setBlock(world, x + 6, y + 2, z + 12, Blocks.air, 0, 3);
		WorldUtils.setBlock(world, x + 7, y + 2, z + 12, Blocks.air, 0, 3);
		WorldUtils.setBlock(world, x + 8, y + 2, z + 12, Blocks.air, 0, 3);
		WorldUtils.setBlock(world, x + 9, y + 2, z + 12, Blocks.air, 0, 3);
		WorldUtils.setBlock(world, x + 10, y + 2, z + 12, Blocks.air, 0, 3);
		WorldUtils.setBlock(world, x + 11, y + 2, z + 12, Blocks.air, 0, 3);
		WorldUtils.setBlock(world, x + 12, y + 2, z + 12, Blocks.air, 0, 3);
		WorldUtils.setBlock(world, x + 13, y + 2, z + 12, Blocks.air, 0, 3);
		WorldUtils.setBlock(world, x + 14, y + 2, z + 12, Blocks.cobblestone_wall, rand.nextInt(2), 3);
		WorldUtils.setBlock(world, x + 15, y + 2, z + 12, Blocks.stonebrick, rand.nextInt(3), 3);
		WorldUtils.setBlock(world, x + 0, y + 2, z + 13, Blocks.air, 0, 3);
		WorldUtils.setBlock(world, x + 1, y + 2, z + 13, Blocks.iron_bars, 0, 3);
		WorldUtils.setBlock(world, x + 2, y + 2, z + 13, Blocks.air, 0, 3);
		WorldUtils.setBlock(world, x + 3, y + 2, z + 13, Blocks.air, 0, 3);
		WorldUtils.setBlock(world, x + 4, y + 2, z + 13, Blocks.air, 0, 3);
		WorldUtils.setBlock(world, x + 5, y + 2, z + 13, Blocks.air, 0, 3);
		WorldUtils.setBlock(world, x + 6, y + 2, z + 13, Blocks.air, 0, 3);
		WorldUtils.setBlock(world, x + 7, y + 2, z + 13, Blocks.air, 0, 3);
		//TODO
		WorldUtils.setBlock(world, x + 8, y + 2, z + 13, ModBlocks.singularitycrystal, 0, 3);
		WorldUtils.setBlock(world, x + 9, y + 2, z + 13, Blocks.air, 0, 3);
		WorldUtils.setBlock(world, x + 10, y + 2, z + 13, Blocks.air, 0, 3);
		WorldUtils.setBlock(world, x + 11, y + 2, z + 13, Blocks.air, 0, 3);
		WorldUtils.setBlock(world, x + 12, y + 2, z + 13, Blocks.air, 0, 3);
		WorldUtils.setBlock(world, x + 13, y + 2, z + 13, Blocks.air, 0, 3);
		WorldUtils.setBlock(world, x + 14, y + 2, z + 13, Blocks.air, 0, 3);
		WorldUtils.setBlock(world, x + 15, y + 2, z + 13, Blocks.iron_bars, 0, 3);
		WorldUtils.setBlock(world, x + 16, y + 2, z + 13, Blocks.air, 0, 3);
		WorldUtils.setBlock(world, x + 0, y + 2, z + 14, Blocks.air, 0, 3);
		WorldUtils.setBlock(world, x + 1, y + 2, z + 14, Blocks.iron_bars, 0, 3);
		WorldUtils.setBlock(world, x + 2, y + 2, z + 14, Blocks.air, 0, 3);
		WorldUtils.setBlock(world, x + 3, y + 2, z + 14, Blocks.air, 0, 3);
		WorldUtils.setBlock(world, x + 4, y + 2, z + 14, Blocks.air, 0, 3);
		WorldUtils.setBlock(world, x + 5, y + 2, z + 14, Blocks.air, 0, 3);
		WorldUtils.setBlock(world, x + 6, y + 2, z + 14, Blocks.air, 0, 3);
		WorldUtils.setBlock(world, x + 7, y + 2, z + 14, Blocks.air, 0, 3);
		WorldUtils.setBlock(world, x + 8, y + 2, z + 14, Blocks.air, 0, 3);
		WorldUtils.setBlock(world, x + 9, y + 2, z + 14, Blocks.air, 0, 3);
		WorldUtils.setBlock(world, x + 10, y + 2, z + 14, Blocks.air, 0, 3);
		WorldUtils.setBlock(world, x + 11, y + 2, z + 14, Blocks.air, 0, 3);
		WorldUtils.setBlock(world, x + 12, y + 2, z + 14, Blocks.air, 0, 3);
		WorldUtils.setBlock(world, x + 13, y + 2, z + 14, Blocks.air, 0, 3);
		WorldUtils.setBlock(world, x + 14, y + 2, z + 14, Blocks.air, 0, 3);
		WorldUtils.setBlock(world, x + 15, y + 2, z + 14, Blocks.iron_bars, 0, 3);
		WorldUtils.setBlock(world, x + 16, y + 2, z + 14, Blocks.air, 0, 3);
		WorldUtils.setBlock(world, x + 1, y + 2, z + 15, Blocks.stonebrick, rand.nextInt(3), 3);
		WorldUtils.setBlock(world, x + 2, y + 2, z + 15, Blocks.cobblestone_wall, rand.nextInt(2), 3);
		WorldUtils.setBlock(world, x + 3, y + 2, z + 15, Blocks.air, 0, 3);
		WorldUtils.setBlock(world, x + 4, y + 2, z + 15, Blocks.air, 0, 3);
		WorldUtils.setBlock(world, x + 5, y + 2, z + 15, Blocks.cobblestone_wall, rand.nextInt(2), 3);
		WorldUtils.setBlock(world, x + 6, y + 2, z + 15, Blocks.air, 0, 3);
		WorldUtils.setBlock(world, x + 7, y + 2, z + 15, Blocks.air, 0, 3);
		WorldUtils.setBlock(world, x + 8, y + 2, z + 15, Blocks.air, 0, 3);
		WorldUtils.setBlock(world, x + 9, y + 2, z + 15, Blocks.air, 0, 3);
		WorldUtils.setBlock(world, x + 10, y + 2, z + 15, Blocks.air, 0, 3);
		WorldUtils.setBlock(world, x + 11, y + 2, z + 15, Blocks.cobblestone_wall, rand.nextInt(2), 3);
		WorldUtils.setBlock(world, x + 12, y + 2, z + 15, Blocks.air, 0, 3);
		WorldUtils.setBlock(world, x + 13, y + 2, z + 15, Blocks.air, 0, 3);
		WorldUtils.setBlock(world, x + 14, y + 2, z + 15, Blocks.cobblestone_wall, rand.nextInt(2), 3);
		WorldUtils.setBlock(world, x + 15, y + 2, z + 15, Blocks.stonebrick, rand.nextInt(3), 3);
		WorldUtils.setBlock(world, x + 1, y + 2, z + 16, Blocks.stonebrick, rand.nextInt(3), 3);
		WorldUtils.setBlock(world, x + 2, y + 2, z + 16, Blocks.stonebrick, rand.nextInt(3), 3);
		WorldUtils.setBlock(world, x + 3, y + 2, z + 16, Blocks.iron_bars, 0, 3);
		WorldUtils.setBlock(world, x + 4, y + 2, z + 16, Blocks.iron_bars, 0, 3);
		WorldUtils.setBlock(world, x + 5, y + 2, z + 16, Blocks.stonebrick, rand.nextInt(3), 3);
		WorldUtils.setBlock(world, x + 6, y + 2, z + 16, Blocks.iron_bars, 0, 3);
		WorldUtils.setBlock(world, x + 7, y + 2, z + 16, Blocks.iron_bars, 0, 3);
		WorldUtils.setBlock(world, x + 8, y + 2, z + 16, Blocks.stonebrick, rand.nextInt(3), 3);
		WorldUtils.setBlock(world, x + 9, y + 2, z + 16, Blocks.iron_bars, 0, 3);
		WorldUtils.setBlock(world, x + 10, y + 2, z + 16, Blocks.iron_bars, 0, 3);
		WorldUtils.setBlock(world, x + 11, y + 2, z + 16, Blocks.stonebrick, rand.nextInt(3), 3);
		WorldUtils.setBlock(world, x + 12, y + 2, z + 16, Blocks.iron_bars, 0, 3);
		WorldUtils.setBlock(world, x + 13, y + 2, z + 16, Blocks.iron_bars, 0, 3);
		WorldUtils.setBlock(world, x + 14, y + 2, z + 16, Blocks.stonebrick, rand.nextInt(3), 3);
		WorldUtils.setBlock(world, x + 15, y + 2, z + 16, Blocks.stonebrick, rand.nextInt(3), 3);
		WorldUtils.setBlock(world, x + 3, y + 2, z + 17, Blocks.air, 0, 3);
		WorldUtils.setBlock(world, x + 4, y + 2, z + 17, Blocks.air, 0, 3);
		WorldUtils.setBlock(world, x + 6, y + 2, z + 17, Blocks.air, 0, 3);
		WorldUtils.setBlock(world, x + 7, y + 2, z + 17, Blocks.air, 0, 3);
		WorldUtils.setBlock(world, x + 9, y + 2, z + 17, Blocks.air, 0, 3);
		WorldUtils.setBlock(world, x + 10, y + 2, z + 17, Blocks.air, 0, 3);
		WorldUtils.setBlock(world, x + 12, y + 2, z + 17, Blocks.air, 0, 3);
		WorldUtils.setBlock(world, x + 13, y + 2, z + 17, Blocks.air, 0, 3);
		WorldUtils.setBlock(world, x + 7, y + 3, z + 0, Blocks.air, 0, 3);
		WorldUtils.setBlock(world, x + 8, y + 3, z + 0, Blocks.air, 0, 3);
		WorldUtils.setBlock(world, x + 9, y + 3, z + 0, Blocks.air, 0, 3);
		WorldUtils.setBlock(world, x + 7, y + 3, z + 1, Blocks.air, 0, 3);
		WorldUtils.setBlock(world, x + 8, y + 3, z + 1, Blocks.air, 0, 3);
		WorldUtils.setBlock(world, x + 9, y + 3, z + 1, Blocks.air, 0, 3);
		WorldUtils.setBlock(world, x + 3, y + 3, z + 2, Blocks.air, 0, 3);
		WorldUtils.setBlock(world, x + 4, y + 3, z + 2, Blocks.air, 0, 3);
		WorldUtils.setBlock(world, x + 6, y + 3, z + 2, Blocks.air, 0, 3);
		WorldUtils.setBlock(world, x + 7, y + 3, z + 2, Blocks.air, 0, 3);
		WorldUtils.setBlock(world, x + 8, y + 3, z + 2, Blocks.air, 0, 3);
		WorldUtils.setBlock(world, x + 9, y + 3, z + 2, Blocks.air, 0, 3);
		WorldUtils.setBlock(world, x + 10, y + 3, z + 2, Blocks.air, 0, 3);
		WorldUtils.setBlock(world, x + 12, y + 3, z + 2, Blocks.air, 0, 3);
		WorldUtils.setBlock(world, x + 13, y + 3, z + 2, Blocks.air, 0, 3);
		WorldUtils.setBlock(world, x + 1, y + 3, z + 3, Blocks.stonebrick, rand.nextInt(3), 3);
		WorldUtils.setBlock(world, x + 2, y + 3, z + 3, Blocks.stonebrick, rand.nextInt(3), 3);
		WorldUtils.setBlock(world, x + 3, y + 3, z + 3, Blocks.iron_bars, 0, 3);
		WorldUtils.setBlock(world, x + 4, y + 3, z + 3, Blocks.iron_bars, 0, 3);
		WorldUtils.setBlock(world, x + 5, y + 3, z + 3, Blocks.stonebrick, rand.nextInt(3), 3);
		WorldUtils.setBlock(world, x + 6, y + 3, z + 3, Blocks.cobblestone_wall, rand.nextInt(2), 3);
		WorldUtils.setBlock(world, x + 7, y + 3, z + 3, Blocks.cobblestone_wall, rand.nextInt(2), 3);
		WorldUtils.setBlock(world, x + 8, y + 3, z + 3, Blocks.air, 0, 3);
		WorldUtils.setBlock(world, x + 9, y + 3, z + 3, Blocks.cobblestone_wall, rand.nextInt(2), 3);
		WorldUtils.setBlock(world, x + 10, y + 3, z + 3, Blocks.cobblestone_wall, rand.nextInt(2), 3);
		WorldUtils.setBlock(world, x + 11, y + 3, z + 3, Blocks.stonebrick, rand.nextInt(3), 3);
		WorldUtils.setBlock(world, x + 12, y + 3, z + 3, Blocks.iron_bars, 0, 3);
		WorldUtils.setBlock(world, x + 13, y + 3, z + 3, Blocks.iron_bars, 0, 3);
		WorldUtils.setBlock(world, x + 14, y + 3, z + 3, Blocks.stonebrick, rand.nextInt(3), 3);
		WorldUtils.setBlock(world, x + 15, y + 3, z + 3, Blocks.stonebrick, rand.nextInt(3), 3);
		WorldUtils.setBlock(world, x + 1, y + 3, z + 4, Blocks.stonebrick, rand.nextInt(3), 3);
		WorldUtils.setBlock(world, x + 2, y + 3, z + 4, Blocks.cobblestone_wall, rand.nextInt(2), 3);
		WorldUtils.setBlock(world, x + 3, y + 3, z + 4, Blocks.air, 0, 3);
		WorldUtils.setBlock(world, x + 4, y + 3, z + 4, Blocks.air, 0, 3);
		WorldUtils.setBlock(world, x + 5, y + 3, z + 4, Blocks.cobblestone_wall, rand.nextInt(2), 3);
		WorldUtils.setBlock(world, x + 6, y + 3, z + 4, Blocks.stonebrick, rand.nextInt(3), 3);
		WorldUtils.setBlock(world, x + 7, y + 3, z + 4, Blocks.air, 0, 3);
		WorldUtils.setBlock(world, x + 8, y + 3, z + 4, Blocks.air, 0, 3);
		WorldUtils.setBlock(world, x + 9, y + 3, z + 4, Blocks.air, 0, 3);
		WorldUtils.setBlock(world, x + 10, y + 3, z + 4, Blocks.stonebrick, rand.nextInt(3), 3);
		WorldUtils.setBlock(world, x + 11, y + 3, z + 4, Blocks.cobblestone_wall, rand.nextInt(2), 3);
		WorldUtils.setBlock(world, x + 12, y + 3, z + 4, Blocks.air, 0, 3);
		WorldUtils.setBlock(world, x + 13, y + 3, z + 4, Blocks.air, 0, 3);
		WorldUtils.setBlock(world, x + 14, y + 3, z + 4, Blocks.cobblestone_wall, rand.nextInt(2), 3);
		WorldUtils.setBlock(world, x + 15, y + 3, z + 4, Blocks.stonebrick, rand.nextInt(3), 3);
		WorldUtils.setBlock(world, x + 0, y + 3, z + 5, Blocks.air, 0, 3);
		WorldUtils.setBlock(world, x + 1, y + 3, z + 5, Blocks.iron_bars, 0, 3);
		WorldUtils.setBlock(world, x + 2, y + 3, z + 5, Blocks.air, 0, 3);
		WorldUtils.setBlock(world, x + 3, y + 3, z + 5, Blocks.air, 0, 3);
		WorldUtils.setBlock(world, x + 4, y + 3, z + 5, Blocks.air, 0, 3);
		WorldUtils.setBlock(world, x + 5, y + 3, z + 5, Blocks.air, 0, 3);
		WorldUtils.setBanner(world, x + 6, y + 3, z + 5, 0, 3, 3);
		WorldUtils.setBlock(world, x + 7, y + 3, z + 5, Blocks.air, 0, 3);
		WorldUtils.setBlock(world, x + 8, y + 3, z + 5, Blocks.air, 0, 3);
		WorldUtils.setBlock(world, x + 9, y + 3, z + 5, Blocks.air, 0, 3);
		WorldUtils.setBanner(world, x + 10, y + 3, z + 5, 0, 3, 3);
		WorldUtils.setBlock(world, x + 11, y + 3, z + 5, Blocks.air, 0, 3);
		WorldUtils.setBlock(world, x + 12, y + 3, z + 5, Blocks.air, 0, 3);
		WorldUtils.setBlock(world, x + 13, y + 3, z + 5, Blocks.air, 0, 3);
		WorldUtils.setBlock(world, x + 14, y + 3, z + 5, Blocks.air, 0, 3);
		WorldUtils.setBlock(world, x + 15, y + 3, z + 5, Blocks.iron_bars, 0, 3);
		WorldUtils.setBlock(world, x + 16, y + 3, z + 5, Blocks.air, 0, 3);
		WorldUtils.setBlock(world, x + 0, y + 3, z + 6, Blocks.air, 0, 3);
		WorldUtils.setBlock(world, x + 1, y + 3, z + 6, Blocks.iron_bars, 0, 3);
		WorldUtils.setBlock(world, x + 2, y + 3, z + 6, Blocks.air, 0, 3);
		WorldUtils.setBlock(world, x + 3, y + 3, z + 6, Blocks.air, 0, 3);
		WorldUtils.setBlock(world, x + 4, y + 3, z + 6, Blocks.air, 0, 3);
		WorldUtils.setBlock(world, x + 5, y + 3, z + 6, Blocks.air, 0, 3);
		WorldUtils.setBlock(world, x + 6, y + 3, z + 6, Blocks.air, 0, 3);
		WorldUtils.setBlock(world, x + 7, y + 3, z + 6, Blocks.air, 0, 3);
		WorldUtils.setBlock(world, x + 8, y + 3, z + 6, Blocks.air, 0, 3);
		WorldUtils.setBlock(world, x + 9, y + 3, z + 6, Blocks.air, 0, 3);
		WorldUtils.setBlock(world, x + 10, y + 3, z + 6, Blocks.air, 0, 3);
		WorldUtils.setBlock(world, x + 11, y + 3, z + 6, Blocks.air, 0, 3);
		WorldUtils.setBlock(world, x + 12, y + 3, z + 6, Blocks.air, 0, 3);
		WorldUtils.setBlock(world, x + 13, y + 3, z + 6, Blocks.air, 0, 3);
		WorldUtils.setBlock(world, x + 14, y + 3, z + 6, Blocks.air, 0, 3);
		WorldUtils.setBlock(world, x + 15, y + 3, z + 6, Blocks.iron_bars, 0, 3);
		WorldUtils.setBlock(world, x + 16, y + 3, z + 6, Blocks.air, 0, 3);
		WorldUtils.setBlock(world, x + 1, y + 3, z + 7, Blocks.stonebrick, rand.nextInt(3), 3);
		WorldUtils.setBlock(world, x + 2, y + 3, z + 7, Blocks.cobblestone_wall, rand.nextInt(2), 3);
		WorldUtils.setBlock(world, x + 3, y + 3, z + 7, Blocks.air, 0, 3);
		WorldUtils.setBlock(world, x + 4, y + 3, z + 7, Blocks.air, 0, 3);
		WorldUtils.setBlock(world, x + 5, y + 3, z + 7, Blocks.air, 0, 3);
		WorldUtils.setBlock(world, x + 6, y + 3, z + 7, Blocks.air, 0, 3);
		WorldUtils.setBlock(world, x + 7, y + 3, z + 7, Blocks.air, 0, 3);
		WorldUtils.setBlock(world, x + 8, y + 3, z + 7, Blocks.air, 0, 3);
		WorldUtils.setBlock(world, x + 9, y + 3, z + 7, Blocks.air, 0, 3);
		WorldUtils.setBlock(world, x + 10, y + 3, z + 7, Blocks.air, 0, 3);
		WorldUtils.setBlock(world, x + 11, y + 3, z + 7, Blocks.air, 0, 3);
		WorldUtils.setBlock(world, x + 12, y + 3, z + 7, Blocks.air, 0, 3);
		WorldUtils.setBlock(world, x + 13, y + 3, z + 7, Blocks.air, 0, 3);
		WorldUtils.setBlock(world, x + 14, y + 3, z + 7, Blocks.cobblestone_wall, rand.nextInt(2), 3);
		WorldUtils.setBlock(world, x + 15, y + 3, z + 7, Blocks.stonebrick, rand.nextInt(3), 3);
		WorldUtils.setBlock(world, x + 0, y + 3, z + 8, Blocks.air, 0, 3);
		WorldUtils.setBlock(world, x + 1, y + 3, z + 8, Blocks.iron_bars, 0, 3);
		WorldUtils.setBlock(world, x + 2, y + 3, z + 8, Blocks.air, 0, 3);
		WorldUtils.setBlock(world, x + 3, y + 3, z + 8, Blocks.air, 0, 3);
		WorldUtils.setBlock(world, x + 4, y + 3, z + 8, Blocks.air, 0, 3);
		WorldUtils.setBlock(world, x + 5, y + 3, z + 8, Blocks.air, 0, 3);
		WorldUtils.setBlock(world, x + 6, y + 3, z + 8, Blocks.air, 0, 3);
		WorldUtils.setBlock(world, x + 7, y + 3, z + 8, Blocks.air, 0, 3);
		WorldUtils.setBlock(world, x + 8, y + 3, z + 8, Blocks.air, 0, 3);
		WorldUtils.setBlock(world, x + 9, y + 3, z + 8, Blocks.air, 0, 3);
		WorldUtils.setBlock(world, x + 10, y + 3, z + 8, Blocks.air, 0, 3);
		WorldUtils.setBlock(world, x + 11, y + 3, z + 8, Blocks.air, 0, 3);
		WorldUtils.setBlock(world, x + 12, y + 3, z + 8, Blocks.air, 0, 3);
		WorldUtils.setBlock(world, x + 13, y + 3, z + 8, Blocks.air, 0, 3);
		WorldUtils.setBlock(world, x + 14, y + 3, z + 8, Blocks.air, 0, 3);
		WorldUtils.setBlock(world, x + 15, y + 3, z + 8, Blocks.iron_bars, 0, 3);
		WorldUtils.setBlock(world, x + 16, y + 3, z + 8, Blocks.air, 0, 3);
		WorldUtils.setBlock(world, x + 1, y + 3, z + 9, Blocks.stonebrick, rand.nextInt(3), 3);
		WorldUtils.setBanner(world, x + 2, y + 3, z + 9, 0, 5, 3);
		WorldUtils.setBlock(world, x + 3, y + 3, z + 9, Blocks.air, 0, 3);
		WorldUtils.setBlock(world, x + 4, y + 3, z + 9, Blocks.air, 0, 3);
		WorldUtils.setBlock(world, x + 5, y + 3, z + 9, Blocks.air, 0, 3);
		WorldUtils.setBlock(world, x + 6, y + 3, z + 9, Blocks.air, 0, 3);
		WorldUtils.setBlock(world, x + 7, y + 3, z + 9, Blocks.air, 0, 3);
		WorldUtils.setBlock(world, x + 8, y + 3, z + 9, Blocks.air, 0, 3);
		WorldUtils.setBlock(world, x + 9, y + 3, z + 9, Blocks.air, 0, 3);
		WorldUtils.setBlock(world, x + 10, y + 3, z + 9, Blocks.air, 0, 3);
		WorldUtils.setBlock(world, x + 11, y + 3, z + 9, Blocks.air, 0, 3);
		WorldUtils.setBlock(world, x + 12, y + 3, z + 9, Blocks.air, 0, 3);
		WorldUtils.setBlock(world, x + 13, y + 3, z + 9, Blocks.air, 0, 3);
		WorldUtils.setBanner(world, x + 14, y + 3, z + 9, 0, 4, 3);
		WorldUtils.setBlock(world, x + 15, y + 3, z + 9, Blocks.stonebrick, rand.nextInt(3), 3);
		WorldUtils.setBlock(world, x + 1, y + 3, z + 10, Blocks.stonebrick, rand.nextInt(3), 3);
		WorldUtils.setBanner(world, x + 2, y + 3, z + 10, 0, 5, 3);
		WorldUtils.setBlock(world, x + 3, y + 3, z + 10, Blocks.air, 0, 3);
		WorldUtils.setBlock(world, x + 4, y + 3, z + 10, Blocks.air, 0, 3);
		WorldUtils.setBlock(world, x + 5, y + 3, z + 10, Blocks.air, 0, 3);
		WorldUtils.setBlock(world, x + 6, y + 3, z + 10, Blocks.air, 0, 3);
		WorldUtils.setBlock(world, x + 7, y + 3, z + 10, Blocks.air, 0, 3);
		WorldUtils.setBlock(world, x + 8, y + 3, z + 10, Blocks.air, 0, 3);
		WorldUtils.setBlock(world, x + 9, y + 3, z + 10, Blocks.air, 0, 3);
		WorldUtils.setBlock(world, x + 10, y + 3, z + 10, Blocks.air, 0, 3);
		WorldUtils.setBlock(world, x + 11, y + 3, z + 10, Blocks.air, 0, 3);
		WorldUtils.setBlock(world, x + 12, y + 3, z + 10, Blocks.air, 0, 3);
		WorldUtils.setBlock(world, x + 13, y + 3, z + 10, Blocks.air, 0, 3);
		WorldUtils.setBanner(world, x + 14, y + 3, z + 10, 0, 4, 3);
		WorldUtils.setBlock(world, x + 15, y + 3, z + 10, Blocks.stonebrick, rand.nextInt(3), 3);
		WorldUtils.setBlock(world, x + 0, y + 3, z + 11, Blocks.air, 0, 3);
		WorldUtils.setBlock(world, x + 1, y + 3, z + 11, Blocks.iron_bars, 0, 3);
		WorldUtils.setBlock(world, x + 2, y + 3, z + 11, Blocks.air, 0, 3);
		WorldUtils.setBlock(world, x + 3, y + 3, z + 11, Blocks.air, 0, 3);
		WorldUtils.setBlock(world, x + 4, y + 3, z + 11, Blocks.air, 0, 3);
		WorldUtils.setBlock(world, x + 5, y + 3, z + 11, Blocks.air, 0, 3);
		WorldUtils.setBlock(world, x + 6, y + 3, z + 11, Blocks.air, 0, 3);
		WorldUtils.setBlock(world, x + 7, y + 3, z + 11, Blocks.air, 0, 3);
		WorldUtils.setBlock(world, x + 8, y + 3, z + 11, Blocks.air, 0, 3);
		WorldUtils.setBlock(world, x + 9, y + 3, z + 11, Blocks.air, 0, 3);
		WorldUtils.setBlock(world, x + 10, y + 3, z + 11, Blocks.air, 0, 3);
		WorldUtils.setBlock(world, x + 11, y + 3, z + 11, Blocks.air, 0, 3);
		WorldUtils.setBlock(world, x + 12, y + 3, z + 11, Blocks.air, 0, 3);
		WorldUtils.setBlock(world, x + 13, y + 3, z + 11, Blocks.air, 0, 3);
		WorldUtils.setBlock(world, x + 14, y + 3, z + 11, Blocks.air, 0, 3);
		WorldUtils.setBlock(world, x + 15, y + 3, z + 11, Blocks.iron_bars, 0, 3);
		WorldUtils.setBlock(world, x + 16, y + 3, z + 11, Blocks.air, 0, 3);
		WorldUtils.setBlock(world, x + 1, y + 3, z + 12, Blocks.stonebrick, rand.nextInt(3), 3);
		WorldUtils.setBlock(world, x + 2, y + 3, z + 12, Blocks.cobblestone_wall, rand.nextInt(2), 3);
		WorldUtils.setBlock(world, x + 3, y + 3, z + 12, Blocks.air, 0, 3);
		WorldUtils.setBlock(world, x + 4, y + 3, z + 12, Blocks.air, 0, 3);
		WorldUtils.setBlock(world, x + 5, y + 3, z + 12, Blocks.air, 0, 3);
		WorldUtils.setBlock(world, x + 6, y + 3, z + 12, Blocks.air, 0, 3);
		WorldUtils.setBlock(world, x + 7, y + 3, z + 12, Blocks.air, 0, 3);
		WorldUtils.setBlock(world, x + 8, y + 3, z + 12, Blocks.air, 0, 3);
		WorldUtils.setBlock(world, x + 9, y + 3, z + 12, Blocks.air, 0, 3);
		WorldUtils.setBlock(world, x + 10, y + 3, z + 12, Blocks.air, 0, 3);
		WorldUtils.setBlock(world, x + 11, y + 3, z + 12, Blocks.air, 0, 3);
		WorldUtils.setBlock(world, x + 12, y + 3, z + 12, Blocks.air, 0, 3);
		WorldUtils.setBlock(world, x + 13, y + 3, z + 12, Blocks.air, 0, 3);
		WorldUtils.setBlock(world, x + 14, y + 3, z + 12, Blocks.cobblestone_wall, rand.nextInt(2), 3);
		WorldUtils.setBlock(world, x + 15, y + 3, z + 12, Blocks.stonebrick, rand.nextInt(3), 3);
		WorldUtils.setBlock(world, x + 0, y + 3, z + 13, Blocks.air, 0, 3);
		WorldUtils.setBlock(world, x + 1, y + 3, z + 13, Blocks.iron_bars, 0, 3);
		WorldUtils.setBlock(world, x + 2, y + 3, z + 13, Blocks.air, 0, 3);
		WorldUtils.setBlock(world, x + 3, y + 3, z + 13, Blocks.air, 0, 3);
		WorldUtils.setBlock(world, x + 4, y + 3, z + 13, Blocks.air, 0, 3);
		WorldUtils.setBlock(world, x + 5, y + 3, z + 13, Blocks.air, 0, 3);
		WorldUtils.setBlock(world, x + 6, y + 3, z + 13, Blocks.air, 0, 3);
		WorldUtils.setBlock(world, x + 7, y + 3, z + 13, Blocks.air, 0, 3);
		WorldUtils.setBlock(world, x + 8, y + 3, z + 13, Blocks.air, 0, 3);
		WorldUtils.setBlock(world, x + 9, y + 3, z + 13, Blocks.air, 0, 3);
		WorldUtils.setBlock(world, x + 10, y + 3, z + 13, Blocks.air, 0, 3);
		WorldUtils.setBlock(world, x + 11, y + 3, z + 13, Blocks.air, 0, 3);
		WorldUtils.setBlock(world, x + 12, y + 3, z + 13, Blocks.air, 0, 3);
		WorldUtils.setBlock(world, x + 13, y + 3, z + 13, Blocks.air, 0, 3);
		WorldUtils.setBlock(world, x + 14, y + 3, z + 13, Blocks.air, 0, 3);
		WorldUtils.setBlock(world, x + 15, y + 3, z + 13, Blocks.iron_bars, 0, 3);
		WorldUtils.setBlock(world, x + 16, y + 3, z + 13, Blocks.air, 0, 3);
		WorldUtils.setBlock(world, x + 0, y + 3, z + 14, Blocks.air, 0, 3);
		WorldUtils.setBlock(world, x + 1, y + 3, z + 14, Blocks.iron_bars, 0, 3);
		WorldUtils.setBlock(world, x + 2, y + 3, z + 14, Blocks.air, 0, 3);
		WorldUtils.setBlock(world, x + 3, y + 3, z + 14, Blocks.air, 0, 3);
		WorldUtils.setBlock(world, x + 4, y + 3, z + 14, Blocks.air, 0, 3);
		WorldUtils.setBlock(world, x + 5, y + 3, z + 14, Blocks.air, 0, 3);
		WorldUtils.setBlock(world, x + 6, y + 3, z + 14, Blocks.air, 0, 3);
		WorldUtils.setBlock(world, x + 7, y + 3, z + 14, Blocks.air, 0, 3);
		WorldUtils.setBlock(world, x + 8, y + 3, z + 14, Blocks.air, 0, 3);
		WorldUtils.setBlock(world, x + 9, y + 3, z + 14, Blocks.air, 0, 3);
		WorldUtils.setBlock(world, x + 10, y + 3, z + 14, Blocks.air, 0, 3);
		WorldUtils.setBlock(world, x + 11, y + 3, z + 14, Blocks.air, 0, 3);
		WorldUtils.setBlock(world, x + 12, y + 3, z + 14, Blocks.air, 0, 3);
		WorldUtils.setBlock(world, x + 13, y + 3, z + 14, Blocks.air, 0, 3);
		WorldUtils.setBlock(world, x + 14, y + 3, z + 14, Blocks.air, 0, 3);
		WorldUtils.setBlock(world, x + 15, y + 3, z + 14, Blocks.iron_bars, 0, 3);
		WorldUtils.setBlock(world, x + 16, y + 3, z + 14, Blocks.air, 0, 3);
		WorldUtils.setBlock(world, x + 1, y + 3, z + 15, Blocks.stonebrick, rand.nextInt(3), 3);
		WorldUtils.setBlock(world, x + 2, y + 3, z + 15, Blocks.cobblestone_wall, rand.nextInt(2), 3);
		WorldUtils.setBlock(world, x + 3, y + 3, z + 15, Blocks.air, 0, 3);
		WorldUtils.setBlock(world, x + 4, y + 3, z + 15, Blocks.air, 0, 3);
		WorldUtils.setBlock(world, x + 5, y + 3, z + 15, Blocks.cobblestone_wall, rand.nextInt(2), 3);
		WorldUtils.setBlock(world, x + 6, y + 3, z + 15, Blocks.air, 0, 3);
		WorldUtils.setBlock(world, x + 7, y + 3, z + 15, Blocks.air, 0, 3);
		//TODO
		WorldUtils.setBanner(world, x + 8, y + 3, z + 15, 1, 2, 3);
		WorldUtils.setBlock(world, x + 9, y + 3, z + 15, Blocks.air, 0, 3);
		WorldUtils.setBlock(world, x + 10, y + 3, z + 15, Blocks.air, 0, 3);
		WorldUtils.setBlock(world, x + 11, y + 3, z + 15, Blocks.cobblestone_wall, rand.nextInt(2), 3);
		WorldUtils.setBlock(world, x + 12, y + 3, z + 15, Blocks.air, 0, 3);
		WorldUtils.setBlock(world, x + 13, y + 3, z + 15, Blocks.air, 0, 3);
		WorldUtils.setBlock(world, x + 14, y + 3, z + 15, Blocks.cobblestone_wall, rand.nextInt(2), 3);
		WorldUtils.setBlock(world, x + 15, y + 3, z + 15, Blocks.stonebrick, rand.nextInt(3), 3);
		WorldUtils.setBlock(world, x + 1, y + 3, z + 16, Blocks.stonebrick, rand.nextInt(3), 3);
		WorldUtils.setBlock(world, x + 2, y + 3, z + 16, Blocks.stonebrick, rand.nextInt(3), 3);
		WorldUtils.setBlock(world, x + 3, y + 3, z + 16, Blocks.iron_bars, 0, 3);
		WorldUtils.setBlock(world, x + 4, y + 3, z + 16, Blocks.iron_bars, 0, 3);
		WorldUtils.setBlock(world, x + 5, y + 3, z + 16, Blocks.stonebrick, rand.nextInt(3), 3);
		WorldUtils.setBlock(world, x + 6, y + 3, z + 16, Blocks.iron_bars, 0, 3);
		WorldUtils.setBlock(world, x + 7, y + 3, z + 16, Blocks.iron_bars, 0, 3);
		WorldUtils.setBlock(world, x + 8, y + 3, z + 16, Blocks.stonebrick, rand.nextInt(3), 3);
		WorldUtils.setBlock(world, x + 9, y + 3, z + 16, Blocks.iron_bars, 0, 3);
		WorldUtils.setBlock(world, x + 10, y + 3, z + 16, Blocks.iron_bars, 0, 3);
		WorldUtils.setBlock(world, x + 11, y + 3, z + 16, Blocks.stonebrick, rand.nextInt(3), 3);
		WorldUtils.setBlock(world, x + 12, y + 3, z + 16, Blocks.iron_bars, 0, 3);
		WorldUtils.setBlock(world, x + 13, y + 3, z + 16, Blocks.iron_bars, 0, 3);
		WorldUtils.setBlock(world, x + 14, y + 3, z + 16, Blocks.stonebrick, rand.nextInt(3), 3);
		WorldUtils.setBlock(world, x + 15, y + 3, z + 16, Blocks.stonebrick, rand.nextInt(3), 3);
		WorldUtils.setBlock(world, x + 3, y + 3, z + 17, Blocks.air, 0, 3);
		WorldUtils.setBlock(world, x + 4, y + 3, z + 17, Blocks.air, 0, 3);
		WorldUtils.setBlock(world, x + 6, y + 3, z + 17, Blocks.air, 0, 3);
		WorldUtils.setBlock(world, x + 7, y + 3, z + 17, Blocks.air, 0, 3);
		WorldUtils.setBlock(world, x + 9, y + 3, z + 17, Blocks.air, 0, 3);
		WorldUtils.setBlock(world, x + 10, y + 3, z + 17, Blocks.air, 0, 3);
		WorldUtils.setBlock(world, x + 12, y + 3, z + 17, Blocks.air, 0, 3);
		WorldUtils.setBlock(world, x + 13, y + 3, z + 17, Blocks.air, 0, 3);
		WorldUtils.setBlock(world, x + 1, y + 4, z + 3, Blocks.stonebrick, rand.nextInt(3), 3);
		WorldUtils.setBlock(world, x + 2, y + 4, z + 3, Blocks.stonebrick, rand.nextInt(3), 3);
		WorldUtils.setBlock(world, x + 3, y + 4, z + 3, Blocks.stonebrick, rand.nextInt(3), 3);
		WorldUtils.setBlock(world, x + 4, y + 4, z + 3, Blocks.stonebrick, rand.nextInt(3), 3);
		WorldUtils.setBlock(world, x + 5, y + 4, z + 3, Blocks.stonebrick, rand.nextInt(3), 3);
		WorldUtils.setBlock(world, x + 6, y + 4, z + 3, Blocks.stonebrick, rand.nextInt(3), 3);
		WorldUtils.setBlock(world, x + 7, y + 4, z + 3, Blocks.stonebrick, rand.nextInt(3), 3);
		WorldUtils.setBlock(world, x + 8, y + 4, z + 3, Blocks.stonebrick, rand.nextInt(3), 3);
		WorldUtils.setBlock(world, x + 9, y + 4, z + 3, Blocks.stonebrick, rand.nextInt(3), 3);
		WorldUtils.setBlock(world, x + 10, y + 4, z + 3, Blocks.stonebrick, rand.nextInt(3), 3);
		WorldUtils.setBlock(world, x + 11, y + 4, z + 3, Blocks.stonebrick, rand.nextInt(3), 3);
		WorldUtils.setBlock(world, x + 12, y + 4, z + 3, Blocks.stonebrick, rand.nextInt(3), 3);
		WorldUtils.setBlock(world, x + 13, y + 4, z + 3, Blocks.stonebrick, rand.nextInt(3), 3);
		WorldUtils.setBlock(world, x + 14, y + 4, z + 3, Blocks.stonebrick, rand.nextInt(3), 3);
		WorldUtils.setBlock(world, x + 15, y + 4, z + 3, Blocks.stonebrick, rand.nextInt(3), 3);
		WorldUtils.setBlock(world, x + 1, y + 4, z + 4, Blocks.stonebrick, rand.nextInt(3), 3);
		WorldUtils.setBlock(world, x + 2, y + 4, z + 4, Blocks.stonebrick, rand.nextInt(3), 3);
		WorldUtils.setBlock(world, x + 3, y + 4, z + 4, Blocks.stonebrick, rand.nextInt(3), 3);
		WorldUtils.setBlock(world, x + 4, y + 4, z + 4, Blocks.stonebrick, rand.nextInt(3), 3);
		WorldUtils.setBlock(world, x + 5, y + 4, z + 4, Blocks.stonebrick, rand.nextInt(3), 3);
		WorldUtils.setBlock(world, x + 6, y + 4, z + 4, Blocks.stonebrick, rand.nextInt(3), 3);
		WorldUtils.setBlock(world, x + 7, y + 4, z + 4, Blocks.stonebrick, rand.nextInt(3), 3);
		WorldUtils.setBlock(world, x + 8, y + 4, z + 4, Blocks.stonebrick, rand.nextInt(3), 3);
		WorldUtils.setBlock(world, x + 9, y + 4, z + 4, Blocks.stonebrick, rand.nextInt(3), 3);
		WorldUtils.setBlock(world, x + 10, y + 4, z + 4, Blocks.stonebrick, rand.nextInt(3), 3);
		WorldUtils.setBlock(world, x + 11, y + 4, z + 4, Blocks.stonebrick, rand.nextInt(3), 3);
		WorldUtils.setBlock(world, x + 12, y + 4, z + 4, Blocks.stonebrick, rand.nextInt(3), 3);
		WorldUtils.setBlock(world, x + 13, y + 4, z + 4, Blocks.stonebrick, rand.nextInt(3), 3);
		WorldUtils.setBlock(world, x + 14, y + 4, z + 4, Blocks.stonebrick, rand.nextInt(3), 3);
		WorldUtils.setBlock(world, x + 15, y + 4, z + 4, Blocks.stonebrick, rand.nextInt(3), 3);
		WorldUtils.setBlock(world, x + 1, y + 4, z + 5, Blocks.stonebrick, rand.nextInt(3), 3);
		WorldUtils.setBlock(world, x + 2, y + 4, z + 5, Blocks.stonebrick, rand.nextInt(3), 3);
		WorldUtils.setBlock(world, x + 3, y + 4, z + 5, Blocks.stonebrick, rand.nextInt(3), 3);
		WorldUtils.setBlock(world, x + 4, y + 4, z + 5, Blocks.stonebrick, rand.nextInt(3), 3);
		WorldUtils.setBlock(world, x + 5, y + 4, z + 5, Blocks.stonebrick, rand.nextInt(3), 3);
		WorldUtils.setBlock(world, x + 6, y + 4, z + 5, Blocks.stonebrick, rand.nextInt(3), 3);
		WorldUtils.setBlock(world, x + 7, y + 4, z + 5, Blocks.stonebrick, rand.nextInt(3), 3);
		WorldUtils.setBlock(world, x + 8, y + 4, z + 5, Blocks.stonebrick, rand.nextInt(3), 3);
		WorldUtils.setBlock(world, x + 9, y + 4, z + 5, Blocks.stonebrick, rand.nextInt(3), 3);
		WorldUtils.setBlock(world, x + 10, y + 4, z + 5, Blocks.stonebrick, rand.nextInt(3), 3);
		WorldUtils.setBlock(world, x + 11, y + 4, z + 5, Blocks.stonebrick, rand.nextInt(3), 3);
		WorldUtils.setBlock(world, x + 12, y + 4, z + 5, Blocks.stonebrick, rand.nextInt(3), 3);
		WorldUtils.setBlock(world, x + 13, y + 4, z + 5, Blocks.stonebrick, rand.nextInt(3), 3);
		WorldUtils.setBlock(world, x + 14, y + 4, z + 5, Blocks.stonebrick, rand.nextInt(3), 3);
		WorldUtils.setBlock(world, x + 15, y + 4, z + 5, Blocks.stonebrick, rand.nextInt(3), 3);
		WorldUtils.setBlock(world, x + 1, y + 4, z + 6, Blocks.stonebrick, rand.nextInt(3), 3);
		WorldUtils.setBlock(world, x + 2, y + 4, z + 6, Blocks.stonebrick, rand.nextInt(3), 3);
		WorldUtils.setBlock(world, x + 3, y + 4, z + 6, Blocks.stonebrick, rand.nextInt(3), 3);
		WorldUtils.setBlock(world, x + 4, y + 4, z + 6, Blocks.stonebrick, rand.nextInt(3), 3);
		WorldUtils.setBlock(world, x + 5, y + 4, z + 6, Blocks.stonebrick, rand.nextInt(3), 3);
		WorldUtils.setBlock(world, x + 6, y + 4, z + 6, Blocks.stonebrick, rand.nextInt(3), 3);
		WorldUtils.setBlock(world, x + 7, y + 4, z + 6, Blocks.stonebrick, rand.nextInt(3), 3);
		WorldUtils.setBlock(world, x + 8, y + 4, z + 6, Blocks.stonebrick, rand.nextInt(3), 3);
		WorldUtils.setBlock(world, x + 9, y + 4, z + 6, Blocks.stonebrick, rand.nextInt(3), 3);
		WorldUtils.setBlock(world, x + 10, y + 4, z + 6, Blocks.stonebrick, rand.nextInt(3), 3);
		WorldUtils.setBlock(world, x + 11, y + 4, z + 6, Blocks.stonebrick, rand.nextInt(3), 3);
		WorldUtils.setBlock(world, x + 12, y + 4, z + 6, Blocks.stonebrick, rand.nextInt(3), 3);
		WorldUtils.setBlock(world, x + 13, y + 4, z + 6, Blocks.stonebrick, rand.nextInt(3), 3);
		WorldUtils.setBlock(world, x + 14, y + 4, z + 6, Blocks.stonebrick, rand.nextInt(3), 3);
		WorldUtils.setBlock(world, x + 15, y + 4, z + 6, Blocks.stonebrick, rand.nextInt(3), 3);
		WorldUtils.setBlock(world, x + 1, y + 4, z + 7, Blocks.stonebrick, rand.nextInt(3), 3);
		WorldUtils.setBlock(world, x + 2, y + 4, z + 7, Blocks.stonebrick, rand.nextInt(3), 3);
		WorldUtils.setBlock(world, x + 3, y + 4, z + 7, Blocks.stonebrick, rand.nextInt(3), 3);
		WorldUtils.setBlock(world, x + 4, y + 4, z + 7, Blocks.stonebrick, rand.nextInt(3), 3);
		WorldUtils.setBlock(world, x + 5, y + 4, z + 7, Blocks.stonebrick, rand.nextInt(3), 3);
		WorldUtils.setBlock(world, x + 6, y + 4, z + 7, Blocks.stonebrick, rand.nextInt(3), 3);
		WorldUtils.setBlock(world, x + 7, y + 4, z + 7, Blocks.stonebrick, rand.nextInt(3), 3);
		WorldUtils.setBlock(world, x + 8, y + 4, z + 7, Blocks.stonebrick, rand.nextInt(3), 3);
		WorldUtils.setBlock(world, x + 9, y + 4, z + 7, Blocks.stonebrick, rand.nextInt(3), 3);
		WorldUtils.setBlock(world, x + 10, y + 4, z + 7, Blocks.stonebrick, rand.nextInt(3), 3);
		WorldUtils.setBlock(world, x + 11, y + 4, z + 7, Blocks.stonebrick, rand.nextInt(3), 3);
		WorldUtils.setBlock(world, x + 12, y + 4, z + 7, Blocks.stonebrick, rand.nextInt(3), 3);
		WorldUtils.setBlock(world, x + 13, y + 4, z + 7, Blocks.stonebrick, rand.nextInt(3), 3);
		WorldUtils.setBlock(world, x + 14, y + 4, z + 7, Blocks.stonebrick, rand.nextInt(3), 3);
		WorldUtils.setBlock(world, x + 15, y + 4, z + 7, Blocks.stonebrick, rand.nextInt(3), 3);
		WorldUtils.setBlock(world, x + 1, y + 4, z + 8, Blocks.stonebrick, rand.nextInt(3), 3);
		WorldUtils.setBlock(world, x + 2, y + 4, z + 8, Blocks.stonebrick, rand.nextInt(3), 3);
		WorldUtils.setBlock(world, x + 3, y + 4, z + 8, Blocks.stonebrick, rand.nextInt(3), 3);
		WorldUtils.setBlock(world, x + 4, y + 4, z + 8, Blocks.stonebrick, rand.nextInt(3), 3);
		WorldUtils.setBlock(world, x + 5, y + 4, z + 8, Blocks.stonebrick, rand.nextInt(3), 3);
		WorldUtils.setBlock(world, x + 6, y + 4, z + 8, Blocks.stonebrick, rand.nextInt(3), 3);
		WorldUtils.setBlock(world, x + 7, y + 4, z + 8, Blocks.stonebrick, rand.nextInt(3), 3);
		WorldUtils.setBlock(world, x + 8, y + 4, z + 8, Blocks.stonebrick, rand.nextInt(3), 3);
		WorldUtils.setBlock(world, x + 9, y + 4, z + 8, Blocks.stonebrick, rand.nextInt(3), 3);
		WorldUtils.setBlock(world, x + 10, y + 4, z + 8, Blocks.stonebrick, rand.nextInt(3), 3);
		WorldUtils.setBlock(world, x + 11, y + 4, z + 8, Blocks.stonebrick, rand.nextInt(3), 3);
		WorldUtils.setBlock(world, x + 12, y + 4, z + 8, Blocks.stonebrick, rand.nextInt(3), 3);
		WorldUtils.setBlock(world, x + 13, y + 4, z + 8, Blocks.stonebrick, rand.nextInt(3), 3);
		WorldUtils.setBlock(world, x + 14, y + 4, z + 8, Blocks.stonebrick, rand.nextInt(3), 3);
		WorldUtils.setBlock(world, x + 15, y + 4, z + 8, Blocks.stonebrick, rand.nextInt(3), 3);
		WorldUtils.setBlock(world, x + 1, y + 4, z + 9, Blocks.stonebrick, rand.nextInt(3), 3);
		WorldUtils.setBlock(world, x + 2, y + 4, z + 9, Blocks.stonebrick, rand.nextInt(3), 3);
		WorldUtils.setBlock(world, x + 3, y + 4, z + 9, Blocks.stonebrick, rand.nextInt(3), 3);
		WorldUtils.setBlock(world, x + 4, y + 4, z + 9, Blocks.stonebrick, rand.nextInt(3), 3);
		WorldUtils.setBlock(world, x + 5, y + 4, z + 9, Blocks.stonebrick, rand.nextInt(3), 3);
		WorldUtils.setBlock(world, x + 6, y + 4, z + 9, Blocks.stonebrick, rand.nextInt(3), 3);
		WorldUtils.setBlock(world, x + 7, y + 4, z + 9, Blocks.stonebrick, rand.nextInt(3), 3);
		WorldUtils.setBlock(world, x + 8, y + 4, z + 9, Blocks.stonebrick, rand.nextInt(3), 3);
		WorldUtils.setBlock(world, x + 9, y + 4, z + 9, Blocks.stonebrick, rand.nextInt(3), 3);
		WorldUtils.setBlock(world, x + 10, y + 4, z + 9, Blocks.stonebrick, rand.nextInt(3), 3);
		WorldUtils.setBlock(world, x + 11, y + 4, z + 9, Blocks.stonebrick, rand.nextInt(3), 3);
		WorldUtils.setBlock(world, x + 12, y + 4, z + 9, Blocks.stonebrick, rand.nextInt(3), 3);
		WorldUtils.setBlock(world, x + 13, y + 4, z + 9, Blocks.stonebrick, rand.nextInt(3), 3);
		WorldUtils.setBlock(world, x + 14, y + 4, z + 9, Blocks.stonebrick, rand.nextInt(3), 3);
		WorldUtils.setBlock(world, x + 15, y + 4, z + 9, Blocks.stonebrick, rand.nextInt(3), 3);
		WorldUtils.setBlock(world, x + 1, y + 4, z + 10, Blocks.stonebrick, rand.nextInt(3), 3);
		WorldUtils.setBlock(world, x + 2, y + 4, z + 10, Blocks.stonebrick, rand.nextInt(3), 3);
		WorldUtils.setBlock(world, x + 3, y + 4, z + 10, Blocks.stonebrick, rand.nextInt(3), 3);
		WorldUtils.setBlock(world, x + 4, y + 4, z + 10, Blocks.stonebrick, rand.nextInt(3), 3);
		WorldUtils.setBlock(world, x + 5, y + 4, z + 10, Blocks.stonebrick, rand.nextInt(3), 3);
		WorldUtils.setBlock(world, x + 6, y + 4, z + 10, Blocks.stonebrick, rand.nextInt(3), 3);
		WorldUtils.setBlock(world, x + 7, y + 4, z + 10, Blocks.stonebrick, rand.nextInt(3), 3);
		WorldUtils.setBlock(world, x + 8, y + 4, z + 10, Blocks.stonebrick, rand.nextInt(3), 3);
		WorldUtils.setBlock(world, x + 9, y + 4, z + 10, Blocks.stonebrick, rand.nextInt(3), 3);
		WorldUtils.setBlock(world, x + 10, y + 4, z + 10, Blocks.stonebrick, rand.nextInt(3), 3);
		WorldUtils.setBlock(world, x + 11, y + 4, z + 10, Blocks.stonebrick, rand.nextInt(3), 3);
		WorldUtils.setBlock(world, x + 12, y + 4, z + 10, Blocks.stonebrick, rand.nextInt(3), 3);
		WorldUtils.setBlock(world, x + 13, y + 4, z + 10, Blocks.stonebrick, rand.nextInt(3), 3);
		WorldUtils.setBlock(world, x + 14, y + 4, z + 10, Blocks.stonebrick, rand.nextInt(3), 3);
		WorldUtils.setBlock(world, x + 15, y + 4, z + 10, Blocks.stonebrick, rand.nextInt(3), 3);
		WorldUtils.setBlock(world, x + 1, y + 4, z + 11, Blocks.stonebrick, rand.nextInt(3), 3);
		WorldUtils.setBlock(world, x + 2, y + 4, z + 11, Blocks.stonebrick, rand.nextInt(3), 3);
		WorldUtils.setBlock(world, x + 3, y + 4, z + 11, Blocks.stonebrick, rand.nextInt(3), 3);
		WorldUtils.setBlock(world, x + 4, y + 4, z + 11, Blocks.stonebrick, rand.nextInt(3), 3);
		WorldUtils.setBlock(world, x + 5, y + 4, z + 11, Blocks.stonebrick, rand.nextInt(3), 3);
		WorldUtils.setBlock(world, x + 6, y + 4, z + 11, Blocks.stonebrick, rand.nextInt(3), 3);
		WorldUtils.setBlock(world, x + 7, y + 4, z + 11, Blocks.stonebrick, rand.nextInt(3), 3);
		WorldUtils.setBlock(world, x + 8, y + 4, z + 11, Blocks.stonebrick, rand.nextInt(3), 3);
		WorldUtils.setBlock(world, x + 9, y + 4, z + 11, Blocks.stonebrick, rand.nextInt(3), 3);
		WorldUtils.setBlock(world, x + 10, y + 4, z + 11, Blocks.stonebrick, rand.nextInt(3), 3);
		WorldUtils.setBlock(world, x + 11, y + 4, z + 11, Blocks.stonebrick, rand.nextInt(3), 3);
		WorldUtils.setBlock(world, x + 12, y + 4, z + 11, Blocks.stonebrick, rand.nextInt(3), 3);
		WorldUtils.setBlock(world, x + 13, y + 4, z + 11, Blocks.stonebrick, rand.nextInt(3), 3);
		WorldUtils.setBlock(world, x + 14, y + 4, z + 11, Blocks.stonebrick, rand.nextInt(3), 3);
		WorldUtils.setBlock(world, x + 15, y + 4, z + 11, Blocks.stonebrick, rand.nextInt(3), 3);
		WorldUtils.setBlock(world, x + 1, y + 4, z + 12, Blocks.stonebrick, rand.nextInt(3), 3);
		WorldUtils.setBlock(world, x + 2, y + 4, z + 12, Blocks.stonebrick, rand.nextInt(3), 3);
		WorldUtils.setBlock(world, x + 3, y + 4, z + 12, Blocks.stonebrick, rand.nextInt(3), 3);
		WorldUtils.setBlock(world, x + 4, y + 4, z + 12, Blocks.stonebrick, rand.nextInt(3), 3);
		WorldUtils.setBlock(world, x + 5, y + 4, z + 12, Blocks.stonebrick, rand.nextInt(3), 3);
		WorldUtils.setBlock(world, x + 6, y + 4, z + 12, Blocks.stonebrick, rand.nextInt(3), 3);
		WorldUtils.setBlock(world, x + 7, y + 4, z + 12, Blocks.stonebrick, rand.nextInt(3), 3);
		WorldUtils.setBlock(world, x + 8, y + 4, z + 12, Blocks.stonebrick, rand.nextInt(3), 3);
		WorldUtils.setBlock(world, x + 9, y + 4, z + 12, Blocks.stonebrick, rand.nextInt(3), 3);
		WorldUtils.setBlock(world, x + 10, y + 4, z + 12, Blocks.stonebrick, rand.nextInt(3), 3);
		WorldUtils.setBlock(world, x + 11, y + 4, z + 12, Blocks.stonebrick, rand.nextInt(3), 3);
		WorldUtils.setBlock(world, x + 12, y + 4, z + 12, Blocks.stonebrick, rand.nextInt(3), 3);
		WorldUtils.setBlock(world, x + 13, y + 4, z + 12, Blocks.stonebrick, rand.nextInt(3), 3);
		WorldUtils.setBlock(world, x + 14, y + 4, z + 12, Blocks.stonebrick, rand.nextInt(3), 3);
		WorldUtils.setBlock(world, x + 15, y + 4, z + 12, Blocks.stonebrick, rand.nextInt(3), 3);
		WorldUtils.setBlock(world, x + 1, y + 4, z + 13, Blocks.stonebrick, rand.nextInt(3), 3);
		WorldUtils.setBlock(world, x + 2, y + 4, z + 13, Blocks.stonebrick, rand.nextInt(3), 3);
		WorldUtils.setBlock(world, x + 3, y + 4, z + 13, Blocks.stonebrick, rand.nextInt(3), 3);
		WorldUtils.setBlock(world, x + 4, y + 4, z + 13, Blocks.stonebrick, rand.nextInt(3), 3);
		WorldUtils.setBlock(world, x + 5, y + 4, z + 13, Blocks.stonebrick, rand.nextInt(3), 3);
		WorldUtils.setBlock(world, x + 6, y + 4, z + 13, Blocks.stonebrick, rand.nextInt(3), 3);
		WorldUtils.setBlock(world, x + 7, y + 4, z + 13, Blocks.stonebrick, rand.nextInt(3), 3);
		WorldUtils.setBlock(world, x + 8, y + 4, z + 13, Blocks.stonebrick, rand.nextInt(3), 3);
		WorldUtils.setBlock(world, x + 9, y + 4, z + 13, Blocks.stonebrick, rand.nextInt(3), 3);
		WorldUtils.setBlock(world, x + 10, y + 4, z + 13, Blocks.stonebrick, rand.nextInt(3), 3);
		WorldUtils.setBlock(world, x + 11, y + 4, z + 13, Blocks.stonebrick, rand.nextInt(3), 3);
		WorldUtils.setBlock(world, x + 12, y + 4, z + 13, Blocks.stonebrick, rand.nextInt(3), 3);
		WorldUtils.setBlock(world, x + 13, y + 4, z + 13, Blocks.stonebrick, rand.nextInt(3), 3);
		WorldUtils.setBlock(world, x + 14, y + 4, z + 13, Blocks.stonebrick, rand.nextInt(3), 3);
		WorldUtils.setBlock(world, x + 15, y + 4, z + 13, Blocks.stonebrick, rand.nextInt(3), 3);
		WorldUtils.setBlock(world, x + 1, y + 4, z + 14, Blocks.stonebrick, rand.nextInt(3), 3);
		WorldUtils.setBlock(world, x + 2, y + 4, z + 14, Blocks.stonebrick, rand.nextInt(3), 3);
		WorldUtils.setBlock(world, x + 3, y + 4, z + 14, Blocks.stonebrick, rand.nextInt(3), 3);
		WorldUtils.setBlock(world, x + 4, y + 4, z + 14, Blocks.stonebrick, rand.nextInt(3), 3);
		WorldUtils.setBlock(world, x + 5, y + 4, z + 14, Blocks.stonebrick, rand.nextInt(3), 3);
		WorldUtils.setBlock(world, x + 6, y + 4, z + 14, Blocks.stonebrick, rand.nextInt(3), 3);
		WorldUtils.setBlock(world, x + 7, y + 4, z + 14, Blocks.stonebrick, rand.nextInt(3), 3);
		WorldUtils.setBlock(world, x + 8, y + 4, z + 14, Blocks.stonebrick, rand.nextInt(3), 3);
		WorldUtils.setBlock(world, x + 9, y + 4, z + 14, Blocks.stonebrick, rand.nextInt(3), 3);
		WorldUtils.setBlock(world, x + 10, y + 4, z + 14, Blocks.stonebrick, rand.nextInt(3), 3);
		WorldUtils.setBlock(world, x + 11, y + 4, z + 14, Blocks.stonebrick, rand.nextInt(3), 3);
		WorldUtils.setBlock(world, x + 12, y + 4, z + 14, Blocks.stonebrick, rand.nextInt(3), 3);
		WorldUtils.setBlock(world, x + 13, y + 4, z + 14, Blocks.stonebrick, rand.nextInt(3), 3);
		WorldUtils.setBlock(world, x + 14, y + 4, z + 14, Blocks.stonebrick, rand.nextInt(3), 3);
		WorldUtils.setBlock(world, x + 15, y + 4, z + 14, Blocks.stonebrick, rand.nextInt(3), 3);
		WorldUtils.setBlock(world, x + 1, y + 4, z + 15, Blocks.stonebrick, rand.nextInt(3), 3);
		WorldUtils.setBlock(world, x + 2, y + 4, z + 15, Blocks.stonebrick, rand.nextInt(3), 3);
		WorldUtils.setBlock(world, x + 3, y + 4, z + 15, Blocks.stonebrick, rand.nextInt(3), 3);
		WorldUtils.setBlock(world, x + 4, y + 4, z + 15, Blocks.stonebrick, rand.nextInt(3), 3);
		WorldUtils.setBlock(world, x + 5, y + 4, z + 15, Blocks.stonebrick, rand.nextInt(3), 3);
		WorldUtils.setBlock(world, x + 6, y + 4, z + 15, Blocks.stonebrick, rand.nextInt(3), 3);
		WorldUtils.setBlock(world, x + 7, y + 4, z + 15, Blocks.stonebrick, rand.nextInt(3), 3);
		WorldUtils.setBlock(world, x + 8, y + 4, z + 15, Blocks.stonebrick, rand.nextInt(3), 3);
		WorldUtils.setBlock(world, x + 9, y + 4, z + 15, Blocks.stonebrick, rand.nextInt(3), 3);
		WorldUtils.setBlock(world, x + 10, y + 4, z + 15, Blocks.stonebrick, rand.nextInt(3), 3);
		WorldUtils.setBlock(world, x + 11, y + 4, z + 15, Blocks.stonebrick, rand.nextInt(3), 3);
		WorldUtils.setBlock(world, x + 12, y + 4, z + 15, Blocks.stonebrick, rand.nextInt(3), 3);
		WorldUtils.setBlock(world, x + 13, y + 4, z + 15, Blocks.stonebrick, rand.nextInt(3), 3);
		WorldUtils.setBlock(world, x + 14, y + 4, z + 15, Blocks.stonebrick, rand.nextInt(3), 3);
		WorldUtils.setBlock(world, x + 15, y + 4, z + 15, Blocks.stonebrick, rand.nextInt(3), 3);
		WorldUtils.setBlock(world, x + 1, y + 4, z + 16, Blocks.stonebrick, rand.nextInt(3), 3);
		WorldUtils.setBlock(world, x + 2, y + 4, z + 16, Blocks.stonebrick, rand.nextInt(3), 3);
		WorldUtils.setBlock(world, x + 3, y + 4, z + 16, Blocks.stonebrick, rand.nextInt(3), 3);
		WorldUtils.setBlock(world, x + 4, y + 4, z + 16, Blocks.stonebrick, rand.nextInt(3), 3);
		WorldUtils.setBlock(world, x + 5, y + 4, z + 16, Blocks.stonebrick, rand.nextInt(3), 3);
		WorldUtils.setBlock(world, x + 6, y + 4, z + 16, Blocks.stonebrick, rand.nextInt(3), 3);
		WorldUtils.setBlock(world, x + 7, y + 4, z + 16, Blocks.stonebrick, rand.nextInt(3), 3);
		WorldUtils.setBlock(world, x + 8, y + 4, z + 16, Blocks.stonebrick, rand.nextInt(3), 3);
		WorldUtils.setBlock(world, x + 9, y + 4, z + 16, Blocks.stonebrick, rand.nextInt(3), 3);
		WorldUtils.setBlock(world, x + 10, y + 4, z + 16, Blocks.stonebrick, rand.nextInt(3), 3);
		WorldUtils.setBlock(world, x + 11, y + 4, z + 16, Blocks.stonebrick, rand.nextInt(3), 3);
		WorldUtils.setBlock(world, x + 12, y + 4, z + 16, Blocks.stonebrick, rand.nextInt(3), 3);
		WorldUtils.setBlock(world, x + 13, y + 4, z + 16, Blocks.stonebrick, rand.nextInt(3), 3);
		WorldUtils.setBlock(world, x + 14, y + 4, z + 16, Blocks.stonebrick, rand.nextInt(3), 3);
		WorldUtils.setBlock(world, x + 15, y + 4, z + 16, Blocks.stonebrick, rand.nextInt(3), 3);
		return true;

	}



}